Workbook

Sheet lot Single yield
A1: Date | B1: Device | C1: Lot | D1: Team | E1: Qty | F1: Die | G1: Single yield | H1: Single yield | I1: All Defect | J1: F02 | K1: F03 | L1: F04 | M1: F05 | N1: F07 | O1: F08 | P1: F12 | Q1: F13 | R1: F15 | S1: F16 | T1: F17 | U1: F18 | V1: F20 | W1: F21 | X1: F22 | Y1: F23 | Z1: F27 | AA1: F30 | AB1: F61 | AC1: F68 | AD1: F69 | AE1: F70 | AF1: F71 | AG1: F72 | AH1: F74 | AI1: F77 | AJ1: F94 | AK1: Map Date | AL1: 備註
A2: 46181 | B2: Weisshorn | C2: 04BW1M | D2: 6446 | E2: 13 | F2: =E2*21 -> 273 | G2: 0.978 | H2: =1-I2/F2 -> 0.97802198 | I2: =SUM(J2:AJ2) -> 6 | J2: 0 | K2: 0 | L2: 0 | M2: 0 | N2: 0 | O2: 0 | P2: 0 | Q2: 0 | R2: 0 | S2: 0 | T2: 0 | U2: 0 | V2: 0 | W2: 6 | X2: 0 | Y2: 0 | Z2: 0 | AA2: 0 | AB2: 0 | AC2: 0 | AD2: 0 | AE2: 0 | AF2: 0 | AG2: 0 | AH2: 0 | AI2: 0 | AJ2: 0 | AK2: 46179
B3: Weisshorn | C3: 04BW1M | D3: 6366 | F3: =E3*21 -> 0 | H3: =1-I3/F3 -> #DIV/0! | I3: =SUM(J3:AI3) -> 0 | J3: 0 | L3: 0 | N3: 0 | O3: 0 | P3: 0 | R3: 0 | S3: 0 | T3: 0 | AB3: 0 | AG3: 0 | AI3: 0 | AJ3: 0 | AL3: No 6366 調站
A4: 46181 | B4: Weisshorn | C4: 04BW1M | D4: 6446 | E4: 13 | F4: =E4*21 -> 273 | G4: 0.978 | H4: =1-I4/F4 -> 0.97802198 | I4: =SUM(J4:AI4) -> 6 | J4: 0 | K4: 0 | L4: 0 | M4: 0 | N4: 0 | O4: 0 | P4: 0 | Q4: 0 | R4: 0 | S4: 0 | T4: 0 | U4: 0 | V4: 0 | W4: 6 | X4: 0 | Y4: 0 | Z4: 0 | AA4: 0 | AB4: 0 | AC4: 0 | AD4: 0 | AE4: 0 | AF4: 0 | AG4: 0 | AH4: 0 | AI4: 0 | AJ4: 0 | AK4: 46179
A5: 46196 | B5: Weisshorn | C5: 04BW1MB001 | D5: 6581 | E5: 1 | F5: =E5*21 -> 21 | G5: 1 | H5: =1-I5/F5 -> 1 | I5: =SUM(J5:AJ5) -> 0 | J5: 0 | K5: 0 | L5: 0 | M5: 0 | N5: 0 | O5: 0 | P5: 0 | Q5: 0 | R5: 0 | S5: 0 | T5: 0 | U5: 0 | V5: 0 | W5: 0 | X5: 0 | Y5: 0 | Z5: 0 | AA5: 0 | AB5: 0 | AC5: 0 | AD5: 0 | AE5: 0 | AF5: 0 | AG5: 0 | AH5: 0 | AI5: 0 | AJ5: 0 | AK5: 46195
A6: 46199 | B6: Weisshorn | C6: 04BW1MB001 | D6: 6601 | E6: 1 | F6: =E6*21 -> 21 | G6: 1 | H6: =1-I6/F6 -> 0.95238095 | I6: =SUM(J6:AJ6) -> 1 | J6: 0 | K6: 0 | L6: 0 | M6: 0 | N6: 0 | O6: 0 | P6: 0 | Q6: 0 | R6: 1 | S6: 0 | T6: 0 | U6: 0 | V6: 0 | W6: 0 | X6: 0 | Y6: 0 | Z6: 0 | AA6: 0 | AB6: 0 | AC6: 0 | AD6: 0 | AE6: 0 | AF6: 0 | AG6: 0 | AH6: 0 | AI6: 0 | AJ6: 0 | AK6: 46198
A7: 46203 | B7: Weisshorn | C7: 04BW1MB002 | D7: 6581 | E7: 1 | F7: =E7*21 -> 21 | G7: 1 | H7: =1-I7/F7 -> 1 | I7: =SUM(J7:AJ7) -> 0 | J7: 0 | K7: 0 | L7: 0 | M7: 0 | N7: 0 | O7: 0 | P7: 0 | Q7: 0 | R7: 0 | S7: 0 | T7: 0 | U7: 0 | V7: 0 | W7: 0 | X7: 0 | Y7: 0 | Z7: 0 | AA7: 0 | AB7: 0 | AC7: 0 | AD7: 0 | AE7: 0 | AF7: 0 | AG7: 0 | AH7: 0 | AI7: 0 | AJ7: 0 | AK7: 46202
A8: 46156 | B8: Weisshorn | C8: 04BW1N | D8: 6446 | E8: 13 | F8: =E8*21 -> 273 | G8: 0.9853 | H8: =1-I8/F8 -> 0.98534799 | I8: =SUM(J8:AJ8) -> 4 | J8: 0 | K8: 0 | L8: 0 | M8: 3 | N8: 0 | O8: 0 | P8: 0 | Q8: 0 | R8: 0 | S8: 0 | T8: 0 | U8: 0 | V8: 1 | W8: 0 | X8: 0 | Y8: 0 | Z8: 0 | AA8: 0 | AB8: 0 | AC8: 0 | AD8: 0 | AE8: 0 | AF8: 0 | AG8: 0 | AH8: 0 | AI8: 0 | AJ8: 0 | AK8: 46153
A9: 46181 | B9: Weisshorn | C9: 04BW1N | D9: 6581 | E9: 4 | F9: =E9*21 -> 84 | G9: 1 | H9: =1-I9/F9 -> 1 | I9: =SUM(J9:AJ9) -> 0 | J9: 0 | K9: 0 | L9: 0 | M9: 0 | N9: 0 | O9: 0 | P9: 0 | Q9: 0 | R9: 0 | S9: 0 | T9: 0 | U9: 0 | V9: 0 | W9: 0 | X9: 0 | Y9: 0 | Z9: 0 | AA9: 0 | AB9: 0 | AC9: 0 | AD9: 0 | AE9: 0 | AF9: 0 | AG9: 0 | AH9: 0 | AI9: 0 | AJ9: 0 | AK9: 46179
A10: 46190 | B10: Weisshorn | C10: 04BW1N | D10: 6601 | E10: 4 | F10: =E10*21 -> 84 | G10: 1 | H10: =1-I10/F10 -> 1 | I10: =SUM(J10:AJ10) -> 0 | J10: 0 | K10: 0 | L10: 0 | M10: 0 | N10: 0 | O10: 0 | P10: 0 | Q10: 0 | R10: 0 | S10: 0 | T10: 0 | U10: 0 | V10: 0 | W10: 0 | X10: 0 | Y10: 0 | Z10: 0 | AA10: 0 | AB10: 0 | AC10: 0 | AD10: 0 | AE10: 0 | AF10: 0 | AG10: 0 | AH10: 0 | AI10: 0 | AJ10: 0 | AK10: 46187
A11: 46195 | B11: Weisshorn | C11: 04BW1N | D11: 6688 | E11: 2 | F11: 42 | G11: 1 | H11: =1-I11/F11 -> 1 | I11: =SUM(J11:AJ11) -> 0 | J11: 0 | K11: 0 | L11: 0 | M11: 0 | N11: 0 | O11: 0 | P11: 0 | Q11: 0 | R11: 0 | S11: 0 | T11: 0 | U11: 0 | V11: 0 | W11: 0 | X11: 0 | Y11: 0 | Z11: 0 | AA11: 0 | AB11: 0 | AC11: 0 | AD11: 0 | AE11: 0 | AF11: 0 | AG11: 0 | AH11: 0 | AI11: 0 | AJ11: 0 | AK11: 46191
A12: 46156 | B12: Weisshorn | C12: 04BW1N | D12: 6446 | E12: 13 | F12: =E12*21 -> 273 | G12: 0.9853 | H12: =1-I12/F12 -> 0.98534799 | I12: =SUM(J12:AI12) -> 4 | J12: 0 | K12: 0 | L12: 0 | M12: 3 | N12: 0 | O12: 0 | P12: 0 | Q12: 0 | R12: 0 | S12: 0 | T12: 0 | U12: 0 | V12: 1 | W12: 0 | X12: 0 | Y12: 0 | Z12: 0 | AA12: 0 | AB12: 0 | AC12: 0 | AD12: 0 | AE12: 0 | AF12: 0 | AG12: 0 | AH12: 0 | AI12: 0 | AJ12: 0 | AK12: 46153
A13: 46168 | B13: Weisshorn | C13: 04BW1NB002 | D13: 6581 | E13: 2 | F13: =E13*21 -> 42 | G13: 1 | H13: =1-I13/F13 -> 1 | I13: =SUM(J13:AJ13) -> 0 | J13: 0 | K13: 0 | L13: 0 | M13: 0 | N13: 0 | O13: 0 | P13: 0 | Q13: 0 | R13: 0 | S13: 0 | T13: 0 | U13: 0 | V13: 0 | W13: 0 | X13: 0 | Y13: 0 | Z13: 0 | AA13: 0 | AB13: 0 | AC13: 0 | AD13: 0 | AE13: 0 | AF13: 0 | AG13: 0 | AH13: 0 | AI13: 0 | AJ13: 0 | AK13: 46168
A14: 46177 | B14: Weisshorn | C14: 04BW1NB002 | D14: 6601 | E14: 2 | F14: =E14*21 -> 42 | G14: 0.9524 | H14: =1-I14/F14 -> 0.95238095 | I14: =SUM(J14:AJ14) -> 2 | J14: 0 | K14: 0 | L14: 0 | M14: 0 | N14: 0 | O14: 0 | P14: 0 | Q14: 0 | R14: 0 | S14: 0 | T14: 0 | U14: 2 | V14: 0 | W14: 0 | X14: 0 | Y14: 0 | Z14: 0 | AA14: 0 | AB14: 0 | AC14: 0 | AD14: 0 | AE14: 0 | AF14: 0 | AG14: 0 | AH14: 0 | AI14: 0 | AJ14: 0 | AK14: 46175
A15: 46202 | B15: Weisshorn | C15: 04BW1NB004 | D15: 6688 | E15: 2 | F15: =E15*21 -> 42 | G15: 1 | H15: =1-I15/F15 -> 1 | I15: =SUM(J15:AJ15) -> 0 | J15: 0 | K15: 0 | L15: 0 | M15: 0 | N15: 0 | O15: 0 | P15: 0 | Q15: 0 | R15: 0 | S15: 0 | T15: 0 | U15: 0 | V15: 0 | W15: 0 | X15: 0 | Y15: 0 | Z15: 0 | AA15: 0 | AB15: 0 | AC15: 0 | AD15: 0 | AE15: 0 | AF15: 0 | AG15: 0 | AH15: 0 | AI15: 0 | AJ15: 0 | AK15: 46202
A16: 46136 | B16: Weisshorn | C16: 04BW2K | D16: 6366 | E16: 9 | F16: =E16*21 -> 189 | G16: 0.9683 | H16: =1-I16/F16 -> 1 | I16: =SUM(J16:AI16) -> 0 | J16: 0 | K16: 0 | L16: 0 | M16: 0 | N16: 0 | O16: 0 | P16: 0 | Q16: 0 | R16: 0 | S16: 0 | T16: 0 | U16: 0 | V16: 0 | W16: 0 | X16: 0 | Y16: 0 | Z16: 0 | AA16: 0 | AB16: 0 | AC16: 0 | AD16: 0 | AE16: 0 | AF16: 0 | AG16: 0 | AH16: 0 | AI16: 0 | AJ16: 0 | AK16: 46136
B17: Weisshorn | C17: 04BW2K | D17: 6446 | F17: =E17*21 -> 0 | H17: =1-I17/F17 -> #DIV/0! | I17: =SUM(J17:AI17) -> 0 | J17: 0 | L17: 0 | O17: 0 | R17: 0 | S17: 0 | T17: 0 | AB17: 0 | AJ17: 0
A18: 46149 | B18: Weisshorn | C18: 04BW2L | D18: 6366 | E18: 13 | F18: =E18*21 -> 273 | G18: 0.9963 | H18: =1-I18/F18 -> 0.996337 | I18: =SUM(J18:AI18) -> 1 | J18: 0 | K18: 0 | L18: 0 | M18: 0 | N18: 1 | O18: 0 | P18: 0 | Q18: 0 | R18: 0 | S18: 0 | T18: 0 | U18: 0 | V18: 0 | W18: 0 | X18: 0 | Y18: 0 | Z18: 0 | AA18: 0 | AB18: 0 | AC18: 0 | AD18: 0 | AE18: 0 | AF18: 0 | AG18: 0 | AH18: 0 | AI18: 0 | AJ18: 0 | AK18: 46149
A19: 46162 | B19: Weisshorn | C19: 04BW2MB001 | D19: 6366 | E19: 2 | F19: =E19*21 -> 42 | G19: 0.9286 | H19: =1-I19/F19 -> 0.92857143 | I19: =SUM(J19:AI19) -> 3 | J19: 0 | K19: 0 | L19: 0 | M19: 0 | N19: 0 | O19: 0 | P19: 2 | Q19: 0 | R19: 0 | S19: 0 | T19: 0 | U19: 0 | V19: 0 | W19: 0 | X19: 1 | Y19: 0 | Z19: 0 | AA19: 0 | AB19: 0 | AC19: 0 | AD19: 0 | AE19: 0 | AF19: 0 | AG19: 0 | AH19: 0 | AI19: 0 | AJ19: 0 | AK19: 46161
A20: 46098 | B20: Weisshorn | C20: 04BW2P | D20: 6446 | E20: 9 | F20: =E20*21 -> 189 | G20: 0.9471 | H20: =1-I20/F20 -> 0.94708995 | I20: =SUM(J20:AJ20) -> 10 | J20: 0 | K20: 0 | L20: 0 | M20: 0 | N20: 0 | O20: 0 | P20: 0 | Q20: 0 | R20: 0 | S20: 0 | T20: 0 | U20: 9 | V20: 0 | W20: 0 | X20: 0 | Y20: 0 | Z20: 0 | AA20: 0 | AB20: 0 | AC20: 0 | AD20: 1 | AE20: 0 | AF20: 0 | AG20: 0 | AH20: 0 | AI20: 0 | AJ20: 0 | AK20: 46098
A21: 46111 | B21: Weisshorn | C21: 04BW2P | D21: 6581 | E21: 8 | F21: =E21*21 -> 168 | G21: 1 | H21: =1-I21/F21 -> 1 | I21: =SUM(J21:AJ21) -> 0 | J21: 0 | K21: 0 | L21: 0 | M21: 0 | N21: 0 | O21: 0 | P21: 0 | Q21: 0 | R21: 0 | S21: 0 | T21: 0 | U21: 0 | V21: 0 | W21: 0 | X21: 0 | Y21: 0 | Z21: 0 | AA21: 0 | AB21: 0 | AC21: 0 | AD21: 0 | AE21: 0 | AF21: 0 | AG21: 0 | AH21: 0 | AI21: 0 | AJ21: 0 | AK21: 46110
A22: 46119 | B22: Weisshorn | C22: 04BW2P | D22: 6601 | E22: 7 | F22: =E22*21 -> 147 | G22: 1 | H22: =1-I22/F22 -> 1 | I22: =SUM(J22:AJ22) -> 0 | J22: 0 | K22: 0 | L22: 0 | M22: 0 | N22: 0 | O22: 0 | P22: 0 | Q22: 0 | R22: 0 | S22: 0 | T22: 0 | U22: 0 | V22: 0 | W22: 0 | X22: 0 | Y22: 0 | Z22: 0 | AA22: 0 | AB22: 0 | AC22: 0 | AD22: 0 | AE22: 0 | AF22: 0 | AG22: 0 | AH22: 0 | AI22: 0 | AJ22: 0 | AK22: 46119
A23: 46092 | B23: Weisshorn | C23: 04BW2P | D23: 6366 | E23: 9 | F23: =E23*21 -> 189 | G23: 0.9947 | H23: =1-I23/F23 -> 0.99470899 | I23: =SUM(J23:AI23) -> 1 | J23: 0 | K23: 0 | L23: 0 | M23: 0 | N23: 0 | O23: 0 | P23: 0 | Q23: 0 | R23: 0 | S23: 0 | T23: 0 | U23: 0 | Y23: 0 | Z23: 0 | AA23: 0 | AB23: 0 | AC23: 0 | AD23: 1 | AE23: 0 | AF23: 0 | AG23: 0 | AH23: 0 | AI23: 0 | AJ23: 0 | AK23: 46091
A24: 46098 | B24: Weisshorn | C24: 04BW2P | D24: 6446 | E24: 9 | F24: =E24*21 -> 189 | G24: 0.9471 | H24: =1-I24/F24 -> 0.94708995 | I24: =SUM(J24:AI24) -> 10 | J24: 0 | K24: 0 | L24: 0 | M24: 0 | N24: 0 | O24: 0 | P24: 0 | Q24: 0 | R24: 0 | S24: 0 | T24: 0 | U24: 9 | Y24: 0 | Z24: 0 | AA24: 0 | AB24: 0 | AC24: 0 | AD24: 1 | AE24: 0 | AF24: 0 | AG24: 0 | AH24: 0 | AI24: 0 | AJ24: 0 | AK24: 46098
B25: Weisshorn | C25: 04BW2PB001 | D25: 6366 | F25: =E25*21 -> 0 | H25: =1-I25/F25 -> #DIV/0! | I25: =SUM(J25:AI25) -> 0 | J25: 0 | L25: 0 | O25: 0 | R25: 0 | S25: 0 | T25: 0 | AB25: 0 | AJ25: 0
B26: Weisshorn | C26: 04BW2PB002 | D26: 6581 | F26: =E26*21 -> 0 | H26: =1-I26/F26 -> #DIV/0! | I26: =SUM(J26:AJ26) -> 0 | N26: 0 | P26: 0 | T26: 0 | AB26: 0 | AE26: 0 | AG26: 0 | AH26: 0 | AI26: 0
A27: 46167 | B27: Weisshorn | C27: 04BW2PB003 | D27: 6601 | E27: 1 | F27: =E27*21 -> 21 | G27: 0.9524 | H27: =1-I27/F27 -> 0.95238095 | I27: =SUM(J27:AJ27) -> 1 | J27: 0 | K27: 0 | L27: 0 | M27: 0 | N27: 0 | O27: 0 | P27: 0 | Q27: 0 | R27: 0 | S27: 0 | T27: 0 | U27: 1 | V27: 0 | W27: 0 | X27: 0 | Y27: 0 | Z27: 0 | AA27: 0 | AB27: 0 | AC27: 0 | AD27: 0 | AE27: 0 | AF27: 0 | AG27: 0 | AH27: 0 | AI27: 0 | AJ27: 0 | AK27: 46163
A28: 46136 | B28: Weisshorn | C28: 04BW2Q | D28: 6366 | E28: 13 | F28: =E28*21 -> 273 | G28: 0.9927 | H28: =1-I28/F28 -> 0.99267399 | I28: =SUM(J28:AI28) -> 2 | J28: 0 | K28: 0 | L28: 0 | M28: 0 | N28: 0 | O28: 0 | P28: 0 | Q28: 0 | R28: 0 | S28: 0 | T28: 0 | U28: 0 | V28: 0 | W28: 0 | X28: 0 | Y28: 0 | Z28: 0 | AA28: 0 | AB28: 0 | AC28: 0 | AD28: 1 | AE28: 0 | AF28: 1 | AG28: 0 | AH28: 0 | AI28: 0 | AJ28: 0 | AK28: 46136
B29: Weisshorn | C29: 04BW2Q | D29: 6446 | I29: =SUM(J29:AI29) -> 0 | J29: 0 | L29: 0 | O29: 0 | R29: 0 | S29: 0 | T29: 0 | AB29: 0 | AJ29: 0
A30: 46009 | B30: Weisshorn | C30: 04BW4SB004 | D30: 6446 | E30: 4 | F30: =E30*21 -> 84 | G30: 0.9762 | H30: =1-I30/F30 -> 0.97619048 | I30: =SUM(J30:AJ30) -> 2 | J30: 0 | K30: 0 | L30: 0 | M30: 0 | N30: 0 | O30: 0 | P30: 0 | Q30: 0 | R30: 0 | S30: 0 | T30: 0 | U30: 0 | V30: 0 | W30: 0 | X30: 0 | Y30: 0 | Z30: 0 | AA30: 0 | AB30: 0 | AC30: 2 | AD30: 0 | AE30: 0 | AF30: 0 | AG30: 0 | AH30: 0 | AI30: 0 | AJ30: 0 | AK30: 45959
A31: - | B31: Weisshorn | C31: 04BW4SB004 | D31: 6581 | F31: =E31*21 -> 0 | H31: =1-I31/F31 -> #DIV/0! | I31: =SUM(J31:AJ31) -> 0 | N31: 0 | P31: 0 | T31: 0 | AB31: 0 | AE31: 0 | AG31: 0 | AH31: 0 | AI31: 0 | AL31: Product comment no need judgment
A32: 46013 | B32: Weisshorn | C32: 04BW4SB004 | D32: 6601 | E32: 4 | F32: =E32*21 -> 84 | G32: 1 | H32: =1-I32/F32 -> 1 | I32: =SUM(J32:AJ32) -> 0 | J32: 0 | K32: 0 | L32: 0 | M32: 0 | N32: 0 | O32: 0 | P32: 0 | Q32: 0 | R32: 0 | S32: 0 | T32: 0 | U32: 0 | V32: 0 | W32: 0 | X32: 0 | Y32: 0 | Z32: 0 | AA32: 0 | AB32: 0 | AC32: 0 | AD32: 0 | AE32: 0 | AF32: 0 | AG32: 0 | AH32: 0 | AI32: 0 | AJ32: 0 | AK32: 45994
A33: 46013 | B33: Weisshorn | C33: 04BW4SB004 | D33: 6688 | E33: 4 | F33: =E33*21 -> 84 | G33: 1 | H33: =1-I33/F33 -> 1 | I33: =SUM(J33:AJ33) -> 0 | J33: 0 | K33: 0 | L33: 0 | M33: 0 | N33: 0 | O33: 0 | P33: 0 | Q33: 0 | R33: 0 | S33: 0 | T33: 0 | U33: 0 | V33: 0 | W33: 0 | X33: 0 | Y33: 0 | Z33: 0 | AA33: 0 | AB33: 0 | AC33: 0 | AD33: 0 | AE33: 0 | AF33: 0 | AG33: 0 | AH33: 0 | AI33: 0 | AJ33: 0 | AK33: 45994
A34: 46013 | B34: Weisshorn | C34: 04BW4SB004 | D34: 6494 | E34: 4 | F34: =E34*21 -> 84 | G34: 1 | H34: =1-I34/F34 -> 1 | I34: =SUM(J34:AJ34) -> 0 | J34: 0 | K34: 0 | L34: 0 | M34: 0 | N34: 0 | O34: 0 | P34: 0 | Q34: 0 | R34: 0 | S34: 0 | T34: 0 | U34: 0 | V34: 0 | W34: 0 | X34: 0 | Y34: 0 | Z34: 0 | AA34: 0 | AB34: 0 | AC34: 0 | AD34: 0 | AE34: 0 | AF34: 0 | AG34: 0 | AH34: 0 | AI34: 0 | AJ34: 0 | AK34: 45989
A35: 46013 | B35: Weisshorn | C35: 04BW4SB004 | E35: 4 | F35: =E35*21 -> 84 | G35: 1 | H35: =1-I35/F35 -> 1 | I35: =SUM(J35:AJ35) -> 0 | J35: 0 | K35: 0 | L35: 0 | M35: 0 | N35: 0 | O35: 0 | P35: 0 | Q35: 0 | R35: 0 | S35: 0 | T35: 0 | U35: 0 | V35: 0 | W35: 0 | X35: 0 | Y35: 0 | Z35: 0 | AA35: 0 | AB35: 0 | AC35: 0 | AD35: 0 | AE35: 0 | AF35: 0 | AG35: 0 | AH35: 0 | AI35: 0 | AJ35: 0 | AK35: 45996
A36: 46209 | B36: AT2 | C36: 11BWBPB002 | D36: 6688 | E36: 1 | F36: =E36*120 -> 120 | G36: 1 | H36: =1-I36/F36 -> 1 | I36: =SUM(J36:AJ36) -> 0 | J36: 0 | K36: 0 | L36: 0 | M36: 0 | N36: 0 | O36: 0 | P36: 0 | Q36: 0 | R36: 0 | S36: 0 | T36: 0 | U36: 0 | V36: 0 | W36: 0 | X36: 0 | Y36: 0 | Z36: 0 | AA36: 0 | AB36: 0 | AC36: 0 | AD36: 0 | AE36: 0 | AF36: 0 | AG36: 0 | AH36: 0 | AI36: 0 | AJ36: 0
A37: 46223 | B37: AT2 | C37: 11BWBPB002 | D37: 6494 | E37: 1 | F37: =E37*120 -> 120 | G37: 1 | H37: =1-I37/F37 -> 1 | I37: =SUM(J37:AJ37) -> 0 | J37: 0 | K37: 0 | L37: 0 | M37: 0 | N37: 0 | O37: 0 | P37: 0 | Q37: 0 | R37: 0 | S37: 0 | T37: 0 | U37: 0 | V37: 0 | W37: 0 | X37: 0 | Y37: 0 | Z37: 0 | AA37: 0 | AB37: 0 | AC37: 0 | AD37: 0 | AE37: 0 | AF37: 0 | AG37: 0 | AH37: 0 | AI37: 0 | AJ37: 0 | AK37: 46222
A38: 46223 | B38: AT2 | C38: 11BWBPB002 | D38: 6905 | E38: 1 | F38: =E38*120 -> 120 | G38: 1 | H38: =1-I38/F38 -> 1 | I38: =SUM(J38:AJ38) -> 0 | J38: 0 | K38: 0 | L38: 0 | M38: 0 | N38: 0 | O38: 0 | P38: 0 | Q38: 0 | R38: 0 | S38: 0 | T38: 0 | U38: 0 | V38: 0 | W38: 0 | X38: 0 | Y38: 0 | Z38: 0 | AA38: 0 | AB38: 0 | AC38: 0 | AD38: 0 | AE38: 0 | AF38: 0 | AG38: 0 | AH38: 0 | AI38: 0 | AJ38: 0 | AK38: 46222
A39: 46219 | B39: MDS1 | C39: 14BW56 | D39: 6601 | E39: 11 | F39: 1870 | G39: 0.99679144 | H39: =1-I39/F39 -> 0.99679144 | I39: =SUM(J39:AJ39) -> 6 | J39: 0 | K39: 0 | L39: 0 | M39: 0 | N39: 0 | O39: 0 | P39: 0 | Q39: 0 | R39: 0 | S39: 0 | T39: 0 | U39: 5 | V39: 0 | W39: 0 | X39: 0 | Y39: 0 | Z39: 1 | AA39: 0 | AB39: 0 | AC39: 0 | AD39: 0 | AE39: 0 | AF39: 0 | AG39: 0 | AH39: 0 | AI39: 0 | AJ39: 0 | AK39: 46214
A40: 46219 | B40: MDS1 | C40: 14BW56 | D40: 6688 | E40: 11 | F40: 1870 | G40: 1 | H40: =1-I40/F40 -> 1 | I40: =SUM(J40:AJ40) -> 0 | J40: 0 | K40: 0 | L40: 0 | M40: 0 | N40: 0 | O40: 0 | P40: 0 | Q40: 0 | R40: 0 | S40: 0 | T40: 0 | U40: 0 | V40: 0 | W40: 0 | X40: 0 | Y40: 0 | Z40: 0 | AA40: 0 | AB40: 0 | AC40: 0 | AD40: 0 | AE40: 0 | AF40: 0 | AG40: 0 | AH40: 0 | AI40: 0 | AJ40: 0 | AK40: 46219
...

Sheet lot Single yield analysis
A1: Week | B1: Date | C1: Device | D1: Lot | E1: Team | F1: Qty | G1: Die | H1: yield | I1: All Defect | J1: Particle lost | K1: F18 | L1: Wait Check | M1: PI Coat | N1: PI Cure | O1: PR Coat | P1: PR Exp | Q1: Sput | R1: Etch | S1: Final | T1: Recon | U1: FOUP | V1: F01 | W1: F02 | X1: F03 | Y1: F04 | Z1: F05 | AA1: F07 | AB1: F08 | AC1: F12 | AD1: F13 | AE1: F15 | AF1: F16 | AG1: F17 | AH1: F20 | AI1: Cu-S Abnormal | AJ1: Small Via | AK1: Glass particle | AL1: F21 | AM1: F22 | AN1: F23 | AO1: F24 | AP1: F27 | AQ1: F30 | AR1: F61 | AS1: F65 | AT1: F68 | AU1: F69 | AV1: F70 | AW1: F71 | AX1: F72 | AY1: F74 | AZ1: F77 | BA1: Others | BB1: Data date | BC1: 備註
B2: 46009 | C2: Weisshorn | D2: 04BW4SB004 | E2: 6446 | F2: 4 | G2: =F2*21 -> 84 | H2: =1-I2/G2 -> 0.97619048 | I2: =SUM(L2:BA2) -> 2 | J2: =K2/G2 -> 0 | K2: =SUM(L2:U2) -> 0 | L2: 0 | M2: 0 | N2: 0 | O2: 0 | P2: 0 | Q2: 0 | R2: 0 | S2: 0 | T2: 0 | U2: 0 | V2: 0 | W2: 0 | X2: 0 | Y2: 0 | Z2: 0 | AA2: 0 | AB2: 0 | AC2: 0 | AD2: 0 | AE2: 0 | AF2: 0 | AG2: 0 | AH2: 0 | AI2: 0 | AJ2: 0 | AK2: 0 | AL2: 0 | AM2: 0 | AN2: 0 | AO2: 0 | AP2: 0 | AQ2: 0 | AR2: 0 | AS2: 0 | AT2: 2 | AU2: 0 | AV2: 0 | AW2: 0 | AX2: 0 | AY2: 0 | AZ2: 0 | BA2: 0
B3: 46009 | C3: Weisshorn | D3: 46BW9S | E3: 6446 | F3: 13 | G3: =F3*21 -> 273 | H3: =1-I3/G3 -> 0.98168498 | I3: =SUM(L3:BA3) -> 5 | J3: =K3/G3 -> 0 | K3: =SUM(L3:U3) -> 0 | L3: 0 | M3: 0 | N3: 0 | O3: 0 | P3: 0 | Q3: 0 | R3: 0 | S3: 0 | T3: 0 | U3: 0 | V3: 0 | W3: 0 | X3: 0 | Y3: 0 | Z3: 2 | AA3: 0 | AB3: 0 | AC3: 0 | AD3: 0 | AE3: 0 | AF3: 0 | AG3: 0 | AH3: 0 | AI3: 3 | AJ3: 0 | AK3: 0 | AL3: 0 | AM3: 0 | AN3: 0 | AO3: 0 | AP3: 0 | AQ3: 0 | AR3: 0 | AS3: 0 | AT3: 0 | AU3: 0 | AV3: 0 | AW3: 0 | AX3: 0 | AY3: 0 | AZ3: 0 | BA3: 0
B4: 46009 | C4: Weisshorn | D4: 46BW9S | E4: 6581 | F4: 3 | G4: =F4*21 -> 63 | H4: =1-I4/G4 -> 0.9047619 | I4: =SUM(L4:BA4) -> 6 | J4: =K4/G4 -> 0.079365079 | K4: =SUM(L4:U4) -> 5 | L4: 0 | M4: 1 | N4: 0 | O4: 0 | P4: 0 | Q4: 3 | R4: 0 | S4: 0 | T4: 1 | U4: 0 | V4: 0 | W4: 0 | X4: 0 | Y4: 0 | Z4: 0 | AA4: 0 | AB4: 0 | AC4: 0 | AD4: 1 | AE4: 0 | AF4: 0 | AG4: 0 | AH4: 0 | AI4: 0 | AJ4: 0 | AK4: 0 | AL4: 0 | AM4: 0 | AN4: 0 | AO4: 0 | AP4: 0 | AQ4: 0 | AR4: 0 | AS4: 0 | AT4: 0 | AU4: 0 | AV4: 0 | AW4: 0 | AX4: 0 | AY4: 0 | AZ4: 0 | BA4: 0
B5: 46009 | C5: Weisshorn | D5: 46BW9S | E5: 6601 | F5: 3 | G5: =F5*21 -> 63 | H5: =1-I5/G5 -> 0.98412698 | I5: =SUM(L5:BA5) -> 1 | J5: =K5/G5 -> 0.015873016 | K5: =SUM(L5:U5) -> 1 | L5: 0 | M5: 1 | N5: 0 | O5: 0 | P5: 0 | Q5: 0 | R5: 0 | S5: 0 | T5: 0 | U5: 0 | V5: 0 | W5: 0 | X5: 0 | Y5: 0 | Z5: 0 | AA5: 0 | AB5: 0 | AC5: 0 | AD5: 0 | AE5: 0 | AF5: 0 | AG5: 0 | AH5: 0 | AI5: 0 | AJ5: 0 | AK5: 0 | AL5: 0 | AM5: 0 | AN5: 0 | AO5: 0 | AP5: 0 | AQ5: 0 | AR5: 0 | AS5: 0 | AT5: 0 | AU5: 0 | AV5: 0 | AW5: 0 | AX5: 0 | AY5: 0 | AZ5: 0 | BA5: 0
B6: 46009 | C6: Weisshorn | D6: 46BW9SB002 | E6: 6581 | F6: 1 | G6: =F6*21 -> 21 | H6: =1-I6/G6 -> 0.95238095 | I6: =SUM(L6:BA6) -> 1 | J6: =K6/G6 -> 0.047619048 | K6: =SUM(L6:U6) -> 1 | L6: 0 | M6: 0 | N6: 0 | O6: 0 | P6: 0 | Q6: 1 | R6: 0 | S6: 0 | T6: 0 | U6: 0 | V6: 0 | W6: 0 | X6: 0 | Y6: 0 | Z6: 0 | AA6: 0 | AB6: 0 | AC6: 0 | AD6: 0 | AE6: 0 | AF6: 0 | AG6: 0 | AH6: 0 | AI6: 0 | AJ6: 0 | AK6: 0 | AL6: 0 | AM6: 0 | AN6: 0 | AO6: 0 | AP6: 0 | AQ6: 0 | AR6: 0 | AS6: 0 | AT6: 0 | AU6: 0 | AV6: 0 | AW6: 0 | AX6: 0 | AY6: 0 | AZ6: 0 | BA6: 0
B7: 46009 | C7: Weisshorn | D7: 46BW9SB002 | E7: 6601 | F7: 1 | G7: =F7*21 -> 21 | H7: =1-I7/G7 -> 1 | I7: =SUM(L7:BA7) -> 0 | J7: =K7/G7 -> 0 | K7: =SUM(L7:U7) -> 0 | L7: 0 | M7: 0 | N7: 0 | O7: 0 | P7: 0 | Q7: 0 | R7: 0 | S7: 0 | T7: 0 | U7: 0 | V7: 0 | W7: 0 | X7: 0 | Y7: 0 | Z7: 0 | AA7: 0 | AB7: 0 | AC7: 0 | AD7: 0 | AE7: 0 | AF7: 0 | AG7: 0 | AH7: 0 | AI7: 0 | AJ7: 0 | AK7: 0 | AL7: 0 | AM7: 0 | AN7: 0 | AO7: 0 | AP7: 0 | AQ7: 0 | AR7: 0 | AS7: 0 | AT7: 0 | AU7: 0 | AV7: 0 | AW7: 0 | AX7: 0 | AY7: 0 | AZ7: 0 | BA7: 0
B8: 46009 | C8: Weisshorn | D8: 46BW9T | E8: 6446 | F8: 13 | G8: =F8*21 -> 273 | H8: =1-I8/G8 -> 0.98534799 | I8: =SUM(L8:BA8) -> 4 | J8: =K8/G8 -> 0 | K8: =SUM(L8:U8) -> 0 | L8: 0 | M8: 0 | N8: 0 | O8: 0 | P8: 0 | Q8: 0 | R8: 0 | S8: 0 | T8: 0 | U8: 0 | V8: 0 | W8: 0 | X8: 0 | Y8: 0 | Z8: 4 | AA8: 0 | AB8: 0 | AC8: 0 | AD8: 0 | AE8: 0 | AF8: 0 | AG8: 0 | AH8: 0 | AI8: 0 | AJ8: 0 | AK8: 0 | AL8: 0 | AM8: 0 | AN8: 0 | AO8: 0 | AP8: 0 | AQ8: 0 | AR8: 0 | AS8: 0 | AT8: 0 | AU8: 0 | AV8: 0 | AW8: 0 | AX8: 0 | AY8: 0 | AZ8: 0 | BA8: 0
B9: 46009 | C9: Weisshorn | D9: 46BW9T | E9: 6581 | F9: 13 | G9: =F9*21 -> 273 | H9: =1-I9/G9 -> 0.996337 | I9: =SUM(L9:BA9) -> 1 | J9: =K9/G9 -> 0 | K9: =SUM(L9:U9) -> 0 | L9: 0 | M9: 0 | N9: 0 | O9: 0 | P9: 0 | Q9: 0 | R9: 0 | S9: 0 | T9: 0 | U9: 0 | V9: 0 | W9: 0 | X9: 0 | Y9: 0 | Z9: 0 | AA9: 0 | AB9: 0 | AC9: 0 | AD9: 0 | AE9: 0 | AF9: 0 | AG9: 0 | AH9: 0 | AI9: 0 | AJ9: 0 | AK9: 0 | AL9: 0 | AM9: 0 | AN9: 0 | AO9: 0 | AP9: 1 | AQ9: 0 | AR9: 0 | AS9: 0 | AT9: 0 | AU9: 0 | AV9: 0 | AW9: 0 | AX9: 0 | AY9: 0 | AZ9: 0 | BA9: 0
B10: 46009 | C10: Weisshorn | D10: 46BW9T | E10: 6601 | F10: 13 | G10: =F10*21 -> 273 | H10: =1-I10/G10 -> 0.996337 | I10: =SUM(L10:BA10) -> 1 | J10: =K10/G10 -> 0.0036630037 | K10: =SUM(L10:U10) -> 1 | L10: 0 | M10: 1 | N10: 0 | O10: 0 | P10: 0 | Q10: 0 | R10: 0 | S10: 0 | T10: 0 | U10: 0 | V10: 0 | W10: 0 | X10: 0 | Y10: 0 | Z10: 0 | AA10: 0 | AB10: 0 | AC10: 0 | AD10: 0 | AE10: 0 | AF10: 0 | AG10: 0 | AH10: 0 | AI10: 0 | AJ10: 0 | AK10: 0 | AL10: 0 | AM10: 0 | AN10: 0 | AO10: 0 | AP10: 0 | AQ10: 0 | AR10: 0 | AS10: 0 | AT10: 0 | AU10: 0 | AV10: 0 | AW10: 0 | AX10: 0 | AY10: 0 | AZ10: 0 | BA10: 0
B11: 46009 | C11: Weisshorn | D11: 46BW9U | E11: 6446 | F11: 13 | G11: =F11*21 -> 273 | H11: =1-I11/G11 -> 0.95604396 | I11: =SUM(L11:BA11) -> 12 | J11: =K11/G11 -> 0.0036630037 | K11: =SUM(L11:U11) -> 1 | L11: 0 | M11: 1 | N11: 0 | O11: 0 | P11: 0 | Q11: 0 | R11: 0 | S11: 0 | T11: 0 | U11: 0 | V11: 0 | W11: 0 | X11: 0 | Y11: 0 | Z11: 11 | AA11: 0 | AB11: 0 | AC11: 0 | AD11: 0 | AE11: 0 | AF11: 0 | AG11: 0 | AH11: 0 | AI11: 0 | AJ11: 0 | AK11: 0 | AL11: 0 | AM11: 0 | AN11: 0 | AO11: 0 | AP11: 0 | AQ11: 0 | AR11: 0 | AS11: 0 | AT11: 0 | AU11: 0 | AV11: 0 | AW11: 0 | AX11: 0 | AY11: 0 | AZ11: 0 | BA11: 0
B12: 46009 | C12: Weisshorn | D12: 46BW9U | E12: 6581 | F12: 13 | G12: =F12*21 -> 273 | H12: =1-I12/G12 -> 0.98168498 | I12: =SUM(L12:BA12) -> 5 | J12: =K12/G12 -> 0.018315018 | K12: =SUM(L12:U12) -> 5 | L12: 0 | M12: 1 | N12: 0 | O12: 0 | P12: 2 | Q12: 2 | R12: 0 | S12: 0 | T12: 0 | U12: 0 | V12: 0 | W12: 0 | X12: 0 | Y12: 0 | Z12: 0 | AA12: 0 | AB12: 0 | AC12: 0 | AD12: 0 | AE12: 0 | AF12: 0 | AG12: 0 | AH12: 0 | AI12: 0 | AJ12: 0 | AK12: 0 | AL12: 0 | AM12: 0 | AN12: 0 | AO12: 0 | AP12: 0 | AQ12: 0 | AR12: 0 | AS12: 0 | AT12: 0 | AU12: 0 | AV12: 0 | AW12: 0 | AX12: 0 | AY12: 0 | AZ12: 0 | BA12: 0
B13: 46009 | C13: Weisshorn | D13: 46BW9U | E13: 6601 | F13: 13 | G13: =F13*21 -> 273 | H13: =1-I13/G13 -> 0.98534799 | I13: =SUM(L13:BA13) -> 4 | J13: =K13/G13 -> 0.014652015 | K13: =SUM(L13:U13) -> 4 | L13: 0 | M13: 0 | N13: 0 | O13: 0 | P13: 0 | Q13: 3 | R13: 0 | S13: 1 | T13: 0 | U13: 0 | V13: 0 | W13: 0 | X13: 0 | Y13: 0 | Z13: 0 | AA13: 0 | AB13: 0 | AC13: 0 | AD13: 0 | AE13: 0 | AF13: 0 | AG13: 0 | AH13: 0 | AI13: 0 | AJ13: 0 | AK13: 0 | AL13: 0 | AM13: 0 | AN13: 0 | AO13: 0 | AP13: 0 | AQ13: 0 | AR13: 0 | AS13: 0 | AT13: 0 | AU13: 0 | AV13: 0 | AW13: 0 | AX13: 0 | AY13: 0 | AZ13: 0 | BA13: 0
A14: W52 | B14: 46013 | C14: Weisshorn | D14: 04BW4SB004 | E14: 6601 | F14: 4 | G14: =F14*21 -> 84 | H14: =1-I14/G14 -> 1 | I14: =SUM(L14:BA14) -> 0 | J14: =K14/G14 -> 0 | K14: =SUM(L14:U14) -> 0 | L14: 0 | M14: 0 | N14: 0 | O14: 0 | P14: 0 | Q14: 0 | R14: 0 | S14: 0 | T14: 0 | U14: 0 | V14: 0 | W14: 0 | X14: 0 | Y14: 0 | Z14: 0 | AA14: 0 | AB14: 0 | AC14: 0 | AD14: 0 | AE14: 0 | AF14: 0 | AG14: 0 | AH14: 0 | AI14: 0 | AJ14: 0 | AK14: 0 | AL14: 0 | AM14: 0 | AN14: 0 | AO14: 0 | AP14: 0 | AQ14: 0 | AR14: 0 | AS14: 0 | AT14: 0 | AU14: 0 | AV14: 0 | AW14: 0 | AX14: 0 | AY14: 0 | AZ14: 0 | BA14: 0
B15: 46013 | C15: Weisshorn | D15: 04BW4SB004 | E15: 6688 | F15: 4 | G15: =F15*21 -> 84 | H15: =1-I15/G15 -> 1 | I15: =SUM(L15:BA15) -> 0 | J15: =K15/G15 -> 0 | K15: =SUM(L15:U15) -> 0 | L15: 0 | M15: 0 | N15: 0 | O15: 0 | P15: 0 | Q15: 0 | R15: 0 | S15: 0 | T15: 0 | U15: 0 | V15: 0 | W15: 0 | X15: 0 | Y15: 0 | Z15: 0 | AA15: 0 | AB15: 0 | AC15: 0 | AD15: 0 | AE15: 0 | AF15: 0 | AG15: 0 | AH15: 0 | AI15: 0 | AJ15: 0 | AK15: 0 | AL15: 0 | AM15: 0 | AN15: 0 | AO15: 0 | AP15: 0 | AQ15: 0 | AR15: 0 | AS15: 0 | AT15: 0 | AU15: 0 | AV15: 0 | AW15: 0 | AX15: 0 | AY15: 0 | AZ15: 0 | BA15: 0
B16: 46013 | C16: Weisshorn | D16: 04BW4SB004 | E16: 6494 | F16: 4 | G16: =F16*21 -> 84 | H16: =1-I16/G16 -> 1 | I16: =SUM(L16:BA16) -> 0 | J16: =K16/G16 -> 0 | K16: =SUM(L16:U16) -> 0 | L16: 0 | M16: 0 | N16: 0 | O16: 0 | P16: 0 | Q16: 0 | R16: 0 | S16: 0 | T16: 0 | U16: 0 | V16: 0 | W16: 0 | X16: 0 | Y16: 0 | Z16: 0 | AA16: 0 | AB16: 0 | AC16: 0 | AD16: 0 | AE16: 0 | AF16: 0 | AG16: 0 | AH16: 0 | AI16: 0 | AJ16: 0 | AK16: 0 | AL16: 0 | AM16: 0 | AN16: 0 | AO16: 0 | AP16: 0 | AQ16: 0 | AR16: 0 | AS16: 0 | AT16: 0 | AU16: 0 | AV16: 0 | AW16: 0 | AX16: 0 | AY16: 0 | AZ16: 0 | BA16: 0
B17: 46013 | C17: Weisshorn | D17: 04BW4SB004 | E17: 6905 | F17: 4 | G17: =F17*21 -> 84 | H17: =1-I17/G17 -> 1 | I17: =SUM(L17:BA17) -> 0 | J17: =K17/G17 -> 0 | K17: =SUM(L17:U17) -> 0 | L17: 0 | M17: 0 | N17: 0 | O17: 0 | P17: 0 | Q17: 0 | R17: 0 | S17: 0 | T17: 0 | U17: 0 | V17: 0 | W17: 0 | X17: 0 | Y17: 0 | Z17: 0 | AA17: 0 | AB17: 0 | AC17: 0 | AD17: 0 | AE17: 0 | AF17: 0 | AG17: 0 | AH17: 0 | AI17: 0 | AJ17: 0 | AK17: 0 | AL17: 0 | AM17: 0 | AN17: 0 | AO17: 0 | AP17: 0 | AQ17: 0 | AR17: 0 | AS17: 0 | AT17: 0 | AU17: 0 | AV17: 0 | AW17: 0 | AX17: 0 | AY17: 0 | AZ17: 0 | BA17: 0
B18: 46013 | C18: Weisshorn | D18: 46BW9S | E18: 6688 | F18: 2 | G18: =F18*21 -> 42 | H18: =1-I18/G18 -> 1 | I18: =SUM(L18:BA18) -> 0 | J18: =K18/G18 -> 0 | K18: =SUM(L18:U18) -> 0 | L18: 0 | M18: 0 | N18: 0 | O18: 0 | P18: 0 | Q18: 0 | R18: 0 | S18: 0 | T18: 0 | U18: 0 | V18: 0 | W18: 0 | X18: 0 | Y18: 0 | Z18: 0 | AA18: 0 | AB18: 0 | AC18: 0 | AD18: 0 | AE18: 0 | AF18: 0 | AG18: 0 | AH18: 0 | AI18: 0 | AJ18: 0 | AK18: 0 | AL18: 0 | AM18: 0 | AN18: 0 | AO18: 0 | AP18: 0 | AQ18: 0 | AR18: 0 | AS18: 0 | AT18: 0 | AU18: 0 | AV18: 0 | AW18: 0 | AX18: 0 | AY18: 0 | AZ18: 0 | BA18: 0
B19: 46013 | C19: Weisshorn | D19: 46BW9SB002 | E19: 6688 | F19: 1 | G19: =F19*21 -> 21 | H19: =1-I19/G19 -> 1 | I19: =SUM(L19:BA19) -> 0 | J19: =K19/G19 -> 0 | K19: =SUM(L19:U19) -> 0 | L19: 0 | M19: 0 | N19: 0 | O19: 0 | P19: 0 | Q19: 0 | R19: 0 | S19: 0 | T19: 0 | U19: 0 | V19: 0 | W19: 0 | X19: 0 | Y19: 0 | Z19: 0 | AA19: 0 | AB19: 0 | AC19: 0 | AD19: 0 | AE19: 0 | AF19: 0 | AG19: 0 | AH19: 0 | AI19: 0 | AJ19: 0 | AK19: 0 | AL19: 0 | AM19: 0 | AN19: 0 | AO19: 0 | AP19: 0 | AQ19: 0 | AR19: 0 | AS19: 0 | AT19: 0 | AU19: 0 | AV19: 0 | AW19: 0 | AX19: 0 | AY19: 0 | AZ19: 0 | BA19: 0
B20: 46013 | C20: Weisshorn | D20: 46BW9SB003 | E20: 6581 | F20: 4 | G20: =F20*21 -> 84 | H20: =1-I20/G20 -> 0.97619048 | I20: =SUM(L20:BA20) -> 2 | J20: =K20/G20 -> 0 | K20: =SUM(L20:U20) -> 0 | L20: 0 | M20: 0 | N20: 0 | O20: 0 | P20: 0 | Q20: 0 | R20: 0 | S20: 0 | T20: 0 | U20: 0 | V20: 0 | W20: 0 | X20: 0 | Y20: 0 | Z20: 0 | AA20: 0 | AB20: 0 | AC20: 0 | AD20: 1 | AE20: 0 | AF20: 0 | AG20: 0 | AH20: 0 | AI20: 1 | AJ20: 0 | AK20: 0 | AL20: 0 | AM20: 0 | AN20: 0 | AO20: 0 | AP20: 0 | AQ20: 0 | AR20: 0 | AS20: 0 | AT20: 0 | AU20: 0 | AV20: 0 | AW20: 0 | AX20: 0 | AY20: 0 | AZ20: 0 | BA20: 0
B21: 46013 | C21: Weisshorn | D21: 46BW9SB003 | E21: 6601 | F21: 4 | G21: =F21*21 -> 84 | H21: =1-I21/G21 -> 1 | I21: =SUM(L21:BA21) -> 0 | J21: =K21/G21 -> 0 | K21: =SUM(L21:U21) -> 0 | L21: 0 | M21: 0 | N21: 0 | O21: 0 | P21: 0 | Q21: 0 | R21: 0 | S21: 0 | T21: 0 | U21: 0 | V21: 0 | W21: 0 | X21: 0 | Y21: 0 | Z21: 0 | AA21: 0 | AB21: 0 | AC21: 0 | AD21: 0 | AE21: 0 | AF21: 0 | AG21: 0 | AH21: 0 | AI21: 0 | AJ21: 0 | AK21: 0 | AL21: 0 | AM21: 0 | AN21: 0 | AO21: 0 | AP21: 0 | AQ21: 0 | AR21: 0 | AS21: 0 | AT21: 0 | AU21: 0 | AV21: 0 | AW21: 0 | AX21: 0 | AY21: 0 | AZ21: 0 | BA21: 0
B22: 46014 | C22: Weisshorn | D22: 46BW9S | E22: 6494 | F22: 2 | G22: =F22*21 -> 42 | H22: =1-I22/G22 -> 1 | I22: =SUM(L22:BA22) -> 0 | J22: =K22/G22 -> 0 | K22: =SUM(L22:U22) -> 0 | L22: 0 | M22: 0 | N22: 0 | O22: 0 | P22: 0 | Q22: 0 | R22: 0 | S22: 0 | T22: 0 | U22: 0 | V22: 0 | W22: 0 | X22: 0 | Y22: 0 | Z22: 0 | AA22: 0 | AB22: 0 | AC22: 0 | AD22: 0 | AE22: 0 | AF22: 0 | AG22: 0 | AH22: 0 | AI22: 0 | AJ22: 0 | AK22: 0 | AL22: 0 | AM22: 0 | AN22: 0 | AO22: 0 | AP22: 0 | AQ22: 0 | AR22: 0 | AS22: 0 | AT22: 0 | AU22: 0 | AV22: 0 | AW22: 0 | AX22: 0 | AY22: 0 | AZ22: 0 | BA22: 0
B23: 46014 | C23: Weisshorn | D23: 46BW9SB002 | E23: 6494 | F23: 1 | G23: =F23*21 -> 21 | H23: =1-I23/G23 -> 1 | I23: =SUM(L23:BA23) -> 0 | J23: =K23/G23 -> 0 | K23: =SUM(L23:U23) -> 0 | L23: 0 | M23: 0 | N23: 0 | O23: 0 | P23: 0 | Q23: 0 | R23: 0 | S23: 0 | T23: 0 | U23: 0 | V23: 0 | W23: 0 | X23: 0 | Y23: 0 | Z23: 0 | AA23: 0 | AB23: 0 | AC23: 0 | AD23: 0 | AE23: 0 | AF23: 0 | AG23: 0 | AH23: 0 | AI23: 0 | AJ23: 0 | AK23: 0 | AL23: 0 | AM23: 0 | AN23: 0 | AO23: 0 | AP23: 0 | AQ23: 0 | AR23: 0 | AS23: 0 | AT23: 0 | AU23: 0 | AV23: 0 | AW23: 0 | AX23: 0 | AY23: 0 | AZ23: 0 | BA23: 0
B24: 46014 | C24: Weisshorn | D24: 46BW9SB004 | E24: 6581 | F24: 2 | G24: =F24*21 -> 42 | H24: =1-I24/G24 -> 0.92857143 | I24: =SUM(L24:BA24) -> 3 | J24: =K24/G24 -> 0.071428571 | K24: =SUM(L24:U24) -> 3 | L24: 0 | M24: 3 | N24: 0 | O24: 0 | P24: 0 | Q24: 0 | R24: 0 | S24: 0 | T24: 0 | U24: 0 | V24: 0 | W24: 0 | X24: 0 | Y24: 0 | Z24: 0 | AA24: 0 | AB24: 0 | AC24: 0 | AD24: 0 | AE24: 0 | AF24: 0 | AG24: 0 | AH24: 0 | AI24: 0 | AJ24: 0 | AK24: 0 | AL24: 0 | AM24: 0 | AN24: 0 | AO24: 0 | AP24: 0 | AQ24: 0 | AR24: 0 | AS24: 0 | AT24: 0 | AU24: 0 | AV24: 0 | AW24: 0 | AX24: 0 | AY24: 0 | AZ24: 0 | BA24: 0
B25: 46014 | C25: Weisshorn | D25: 46BW9SB004 | E25: 6601 | F25: 2 | G25: =F25*21 -> 42 | H25: =1-I25/G25 -> 0.97619048 | I25: =SUM(L25:BA25) -> 1 | J25: =K25/G25 -> 0.023809524 | K25: =SUM(L25:U25) -> 1 | L25: 0 | M25: 0 | N25: 0 | O25: 0 | P25: 0 | Q25: 0 | R25: 0 | S25: 1 | T25: 0 | U25: 0 | V25: 0 | W25: 0 | X25: 0 | Y25: 0 | Z25: 0 | AA25: 0 | AB25: 0 | AC25: 0 | AD25: 0 | AE25: 0 | AF25: 0 | AG25: 0 | AH25: 0 | AI25: 0 | AJ25: 0 | AK25: 0 | AL25: 0 | AM25: 0 | AN25: 0 | AO25: 0 | AP25: 0 | AQ25: 0 | AR25: 0 | AS25: 0 | AT25: 0 | AU25: 0 | AV25: 0 | AW25: 0 | AX25: 0 | AY25: 0 | AZ25: 0 | BA25: 0
B26: 46015 | C26: Weisshorn | D26: 46BW9T | E26: 6688 | F26: 12 | G26: =F26*21 -> 252 | H26: =1-I26/G26 -> 0.98412698 | I26: =SUM(L26:BA26) -> 4 | J26: =K26/G26 -> 0.015873016 | K26: =SUM(L26:U26) -> 4 | L26: 0 | M26: 0 | N26: 0 | O26: 0 | P26: 4 | Q26: 0 | R26: 0 | S26: 0 | T26: 0 | U26: 0 | V26: 0 | W26: 0 | X26: 0 | Y26: 0 | Z26: 0 | AA26: 0 | AB26: 0 | AC26: 0 | AD26: 0 | AE26: 0 | AF26: 0 | AG26: 0 | AH26: 0 | AI26: 0 | AJ26: 0 | AK26: 0 | AL26: 0 | AM26: 0 | AN26: 0 | AO26: 0 | AP26: 0 | AQ26: 0 | AR26: 0 | AS26: 0 | AT26: 0 | AU26: 0 | AV26: 0 | AW26: 0 | AX26: 0 | AY26: 0 | AZ26: 0 | BA26: 0
B27: 46015 | C27: Weisshorn | D27: 46BW9U | E27: 6688 | F27: 13 | G27: =F27*21 -> 273 | H27: =1-I27/G27 -> 0.97069597 | I27: =SUM(L27:BA27) -> 8 | J27: =K27/G27 -> 0.029304029 | K27: =SUM(L27:U27) -> 8 | L27: 0 | M27: 0 | N27: 0 | O27: 0 | P27: 7 | Q27: 0 | R27: 0 | S27: 1 | T27: 0 | U27: 0 | V27: 0 | W27: 0 | X27: 0 | Y27: 0 | Z27: 0 | AA27: 0 | AB27: 0 | AC27: 0 | AD27: 0 | AE27: 0 | AF27: 0 | AG27: 0 | AH27: 0 | AI27: 0 | AJ27: 0 | AK27: 0 | AL27: 0 | AM27: 0 | AN27: 0 | AO27: 0 | AP27: 0 | AQ27: 0 | AR27: 0 | AS27: 0 | AT27: 0 | AU27: 0 | AV27: 0 | AW27: 0 | AX27: 0 | AY27: 0 | AZ27: 0 | BA27: 0
A28: W01 | B28: 46020 | C28: Weisshorn | D28: 46BW9S | E28: 6905 | F28: 2 | G28: =F28*21 -> 42 | H28: =1-I28/G28 -> 1 | I28: =SUM(L28:BA28) -> 0 | J28: =K28/G28 -> 0 | K28: =SUM(L28:U28) -> 0 | L28: 0 | M28: 0 | N28: 0 | O28: 0 | P28: 0 | Q28: 0 | R28: 0 | S28: 0 | T28: 0 | U28: 0 | V28: 0 | W28: 0 | X28: 0 | Y28: 0 | Z28: 0 | AA28: 0 | AB28: 0 | AC28: 0 | AD28: 0 | AE28: 0 | AF28: 0 | AG28: 0 | AH28: 0 | AI28: 0 | AJ28: 0 | AK28: 0 | AL28: 0 | AM28: 0 | AN28: 0 | AO28: 0 | AP28: 0 | AQ28: 0 | AR28: 0 | AS28: 0 | AT28: 0 | AU28: 0 | AV28: 0 | AW28: 0 | AX28: 0 | AY28: 0 | AZ28: 0 | BA28: 0
B29: 46020 | C29: Weisshorn | D29: 46BW9SB002 | E29: 6905 | F29: 1 | G29: =F29*21 -> 21 | H29: =1-I29/G29 -> 1 | I29: =SUM(L29:BA29) -> 0 | J29: =K29/G29 -> 0 | K29: =SUM(L29:U29) -> 0 | L29: 0 | M29: 0 | N29: 0 | O29: 0 | P29: 0 | Q29: 0 | R29: 0 | S29: 0 | T29: 0 | U29: 0 | V29: 0 | W29: 0 | X29: 0 | Y29: 0 | Z29: 0 | AA29: 0 | AB29: 0 | AC29: 0 | AD29: 0 | AE29: 0 | AF29: 0 | AG29: 0 | AH29: 0 | AI29: 0 | AJ29: 0 | AK29: 0 | AL29: 0 | AM29: 0 | AN29: 0 | AO29: 0 | AP29: 0 | AQ29: 0 | AR29: 0 | AS29: 0 | AT29: 0 | AU29: 0 | AV29: 0 | AW29: 0 | AX29: 0 | AY29: 0 | AZ29: 0 | BA29: 0
B30: 46020 | C30: Weisshorn | D30: 46BW9SB003 | E30: 6688 | F30: 3 | G30: =F30*21 -> 63 | H30: =1-I30/G30 -> 1 | I30: =SUM(L30:BA30) -> 0 | J30: =K30/G30 -> 0 | K30: =SUM(L30:U30) -> 0 | L30: 0 | M30: 0 | N30: 0 | O30: 0 | P30: 0 | Q30: 0 | R30: 0 | S30: 0 | T30: 0 | U30: 0 | V30: 0 | W30: 0 | X30: 0 | Y30: 0 | Z30: 0 | AA30: 0 | AB30: 0 | AC30: 0 | AD30: 0 | AE30: 0 | AF30: 0 | AG30: 0 | AH30: 0 | AI30: 0 | AJ30: 0 | AK30: 0 | AL30: 0 | AM30: 0 | AN30: 0 | AO30: 0 | AP30: 0 | AQ30: 0 | AR30: 0 | AS30: 0 | AT30: 0 | AU30: 0 | AV30: 0 | AW30: 0 | AX30: 0 | AY30: 0 | AZ30: 0 | BA30: 0
B31: 46020 | C31: Weisshorn | D31: 46BW9SB006 | E31: 6688 | F31: 1 | G31: =F31*21 -> 21 | H31: =1-I31/G31 -> 1 | I31: =SUM(L31:BA31) -> 0 | J31: =K31/G31 -> 0 | K31: =SUM(L31:U31) -> 0 | L31: 0 | M31: 0 | N31: 0 | O31: 0 | P31: 0 | Q31: 0 | R31: 0 | S31: 0 | T31: 0 | U31: 0 | V31: 0 | W31: 0 | X31: 0 | Y31: 0 | Z31: 0 | AA31: 0 | AB31: 0 | AC31: 0 | AD31: 0 | AE31: 0 | AF31: 0 | AG31: 0 | AH31: 0 | AI31: 0 | AJ31: 0 | AK31: 0 | AL31: 0 | AM31: 0 | AN31: 0 | AO31: 0 | AP31: 0 | AQ31: 0 | AR31: 0 | AS31: 0 | AT31: 0 | AU31: 0 | AV31: 0 | AW31: 0 | AX31: 0 | AY31: 0 | AZ31: 0 | BA31: 0
B32: 46021 | C32: Weisshorn | D32: 46BW9SB006 | E32: 6494 | F32: 1 | G32: =F32*21 -> 21 | H32: =1-I32/G32 -> 1 | I32: =SUM(L32:BA32) -> 0 | J32: =K32/G32 -> 0 | K32: =SUM(L32:U32) -> 0 | L32: 0 | M32: 0 | N32: 0 | O32: 0 | P32: 0 | Q32: 0 | R32: 0 | S32: 0 | T32: 0 | U32: 0 | V32: 0 | W32: 0 | X32: 0 | Y32: 0 | Z32: 0 | AA32: 0 | AB32: 0 | AC32: 0 | AD32: 0 | AE32: 0 | AF32: 0 | AG32: 0 | AH32: 0 | AI32: 0 | AJ32: 0 | AK32: 0 | AL32: 0 | AM32: 0 | AN32: 0 | AO32: 0 | AP32: 0 | AQ32: 0 | AR32: 0 | AS32: 0 | AT32: 0 | AU32: 0 | AV32: 0 | AW32: 0 | AX32: 0 | AY32: 0 | AZ32: 0 | BA32: 0
B33: 46021 | C33: Weisshorn | D33: 46BW9TB001 | E33: 6688 | F33: 1 | G33: =F33*21 -> 21 | H33: =1-I33/G33 -> 1 | I33: =SUM(L33:BA33) -> 0 | J33: =K33/G33 -> 0 | K33: =SUM(L33:U33) -> 0 | L33: 0 | M33: 0 | N33: 0 | O33: 0 | P33: 0 | Q33: 0 | R33: 0 | S33: 0 | T33: 0 | U33: 0 | V33: 0 | W33: 0 | X33: 0 | Y33: 0 | Z33: 0 | AA33: 0 | AB33: 0 | AC33: 0 | AD33: 0 | AE33: 0 | AF33: 0 | AG33: 0 | AH33: 0 | AI33: 0 | AJ33: 0 | AK33: 0 | AL33: 0 | AM33: 0 | AN33: 0 | AO33: 0 | AP33: 0 | AQ33: 0 | AR33: 0 | AS33: 0 | AT33: 0 | AU33: 0 | AV33: 0 | AW33: 0 | AX33: 0 | AY33: 0 | AZ33: 0 | BA33: 0
B34: 46024 | C34: Weisshorn | D34: 46BW9T | E34: 6494 | F34: 12 | G34: =F34*21 -> 252 | H34: =1-I34/G34 -> 0.99603175 | I34: =SUM(L34:BA34) -> 1 | J34: =K34/G34 -> 0.003968254 | K34: =SUM(L34:U34) -> 1 | L34: 0 | M34: 0 | N34: 0 | O34: 0 | P34: 0 | Q34: 1 | R34: 0 | S34: 0 | T34: 0 | U34: 0 | V34: 0 | W34: 0 | X34: 0 | Y34: 0 | Z34: 0 | AA34: 0 | AB34: 0 | AC34: 0 | AD34: 0 | AE34: 0 | AF34: 0 | AG34: 0 | AH34: 0 | AI34: 0 | AJ34: 0 | AK34: 0 | AL34: 0 | AM34: 0 | AN34: 0 | AO34: 0 | AP34: 0 | AQ34: 0 | AR34: 0 | AS34: 0 | AT34: 0 | AU34: 0 | AV34: 0 | AW34: 0 | AX34: 0 | AY34: 0 | AZ34: 0 | BA34: 0
A35: W02 | B35: 46027 | C35: Weisshorn | D35: 46BW9SB006 | E35: 6905 | F35: 1 | G35: =F35*21 -> 21 | H35: =1-I35/G35 -> 1 | I35: =SUM(L35:BA35) -> 0 | J35: =K35/G35 -> 0 | K35: =SUM(L35:U35) -> 0 | L35: 0 | M35: 0 | N35: 0 | O35: 0 | P35: 0 | Q35: 0 | R35: 0 | S35: 0 | T35: 0 | U35: 0 | V35: 0 | W35: 0 | X35: 0 | Y35: 0 | Z35: 0 | AA35: 0 | AB35: 0 | AC35: 0 | AD35: 0 | AE35: 0 | AF35: 0 | AG35: 0 | AH35: 0 | AI35: 0 | AJ35: 0 | AK35: 0 | AL35: 0 | AM35: 0 | AN35: 0 | AO35: 0 | AP35: 0 | AQ35: 0 | AR35: 0 | AS35: 0 | AT35: 0 | AU35: 0 | AV35: 0 | AW35: 0 | AX35: 0 | AY35: 0 | AZ35: 0 | BA35: 0
B36: 46027 | C36: Weisshorn | D36: 46BW9SB001 | E36: 6581 | F36: 2 | G36: =F36*21 -> 42 | H36: =1-I36/G36 -> 1 | I36: =SUM(L36:BA36) -> 0 | J36: =K36/G36 -> 0 | K36: =SUM(L36:U36) -> 0 | L36: 0 | M36: 0 | N36: 0 | O36: 0 | P36: 0 | Q36: 0 | R36: 0 | S36: 0 | T36: 0 | U36: 0 | V36: 0 | W36: 0 | X36: 0 | Y36: 0 | Z36: 0 | AA36: 0 | AB36: 0 | AC36: 0 | AD36: 0 | AE36: 0 | AF36: 0 | AG36: 0 | AH36: 0 | AI36: 0 | AJ36: 0 | AK36: 0 | AL36: 0 | AM36: 0 | AN36: 0 | AO36: 0 | AP36: 0 | AQ36: 0 | AR36: 0 | AS36: 0 | AT36: 0 | AU36: 0 | AV36: 0 | AW36: 0 | AX36: 0 | AY36: 0 | AZ36: 0 | BA36: 0
B37: 46027 | C37: Weisshorn | D37: 46BW9SB004 | E37: 6905 | F37: 1 | G37: =F37*21 -> 21 | H37: =1-I37/G37 -> 1 | I37: =SUM(L37:BA37) -> 0 | J37: =K37/G37 -> 0 | K37: =SUM(L37:U37) -> 0 | L37: 0 | M37: 0 | N37: 0 | O37: 0 | P37: 0 | Q37: 0 | R37: 0 | S37: 0 | T37: 0 | U37: 0 | V37: 0 | W37: 0 | X37: 0 | Y37: 0 | Z37: 0 | AA37: 0 | AB37: 0 | AC37: 0 | AD37: 0 | AE37: 0 | AF37: 0 | AG37: 0 | AH37: 0 | AI37: 0 | AJ37: 0 | AK37: 0 | AL37: 0 | AM37: 0 | AN37: 0 | AO37: 0 | AP37: 0 | AQ37: 0 | AR37: 0 | AS37: 0 | AT37: 0 | AU37: 0 | AV37: 0 | AW37: 0 | AX37: 0 | AY37: 0 | AZ37: 0 | BA37: 0
B38: 46027 | C38: Weisshorn | D38: 46BW9SB004 | E38: 6688 | F38: 2 | G38: =F38*21 -> 42 | H38: =1-I38/G38 -> 0.9047619 | I38: =SUM(L38:BA38) -> 4 | J38: =K38/G38 -> 0.071428571 | K38: =SUM(L38:U38) -> 3 | L38: 0 | M38: 3 | N38: 0 | O38: 0 | P38: 0 | Q38: 0 | R38: 0 | S38: 0 | T38: 0 | U38: 0 | V38: 0 | W38: 0 | X38: 0 | Y38: 0 | Z38: 0 | AA38: 0 | AB38: 0 | AC38: 0 | AD38: 1 | AE38: 0 | AF38: 0 | AG38: 0 | AH38: 0 | AI38: 0 | AJ38: 0 | AK38: 0 | AL38: 0 | AM38: 0 | AN38: 0 | AO38: 0 | AP38: 0 | AQ38: 0 | AR38: 0 | AS38: 0 | AT38: 0 | AU38: 0 | AV38: 0 | AW38: 0 | AX38: 0 | AY38: 0 | AZ38: 0 | BA38: 0
B39: 46027 | C39: Weisshorn | D39: 46BW9SB004 | E39: 6494 | F39: 2 | G39: =F39*21 -> 42 | H39: =1-I39/G39 -> 0.95238095 | I39: =SUM(L39:BA39) -> 2 | J39: =K39/G39 -> 0.047619048 | K39: =SUM(L39:U39) -> 2 | L39: 0 | M39: 1 | N39: 0 | O39: 0 | P39: 0 | Q39: 0 | R39: 0 | S39: 1 | T39: 0 | U39: 0 | V39: 0 | W39: 0 | X39: 0 | Y39: 0 | Z39: 0 | AA39: 0 | AB39: 0 | AC39: 0 | AD39: 0 | AE39: 0 | AF39: 0 | AG39: 0 | AH39: 0 | AI39: 0 | AJ39: 0 | AK39: 0 | AL39: 0 | AM39: 0 | AN39: 0 | AO39: 0 | AP39: 0 | AQ39: 0 | AR39: 0 | AS39: 0 | AT39: 0 | AU39: 0 | AV39: 0 | AW39: 0 | AX39: 0 | AY39: 0 | AZ39: 0 | BA39: 0
B40: 46028 | C40: Weisshorn | D40: 46BW9SB001 | E40: 6601 | F40: 2 | G40: =F40*21 -> 42 | H40: =1-I40/G40 -> 1 | I40: =SUM(L40:BA40) -> 0 | J40: =K40/G40 -> 0 | K40: =SUM(L40:U40) -> 0 | L40: 0 | M40: 0 | N40: 0 | O40: 0 | P40: 0 | Q40: 0 | R40: 0 | S40: 0 | T40: 0 | U40: 0 | V40: 0 | W40: 0 | X40: 0 | Y40: 0 | Z40: 0 | AA40: 0 | AB40: 0 | AC40: 0 | AD40: 0 | AE40: 0 | AF40: 0 | AG40: 0 | AH40: 0 | AI40: 0 | AJ40: 0 | AK40: 0 | AL40: 0 | AM40: 0 | AN40: 0 | AO40: 0 | AP40: 0 | AQ40: 0 | AR40: 0 | AS40: 0 | AT40: 0 | AU40: 0 | AV40: 0 | AW40: 0 | AX40: 0 | AY40: 0 | AZ40: 0 | BA40: 0
...

Sheet lot merge AEI yield analysis 
A1: Week | B1: Date | C1: Device | D1: Lot | E1: Layer | F1: Qty | G1: Die | H1: yield | I1: All Defect | J1: Particle lost | K1: F18 | L1: Wait check | M1: PI Coat | N1: PI Cure | O1: PR Coat | P1: PR Exp | Q1: Sput | R1: Etch | S1: Final | T1: Recon | U1: FOUP | V1: F02 | W1: F03 | X1: F04 | Y1: F05 | Z1: F07 | AA1: F08 | AB1: F12 | AC1: F13 | AD1: F15 | AE1: F16 | AF1: F17 | AG1: F20 | AH1: Cu-S Abnormal | AI1: Small Via | AJ1: Glass particle | AK1: F21 | AL1: F22 | AM1: F23 | AN1: F27 | AO1: F30 | AP1: F61 | AQ1: F68 | AR1: F69 | AS1: F70 | AT1: F71 | AU1: F72 | AV1: F74 | AW1: F77 | AX1: F94 | AY1: 備註
B2: 46168 | C2: Weisshorn | D2: 15BW42B003 | E2: L3 | F2: 3 | G2: =F2*21 -> 63 | H2: =1-I2/G2 -> 0.98412698 | I2: =SUM(L2:AX2) -> 1 | J2: =K2/G2 -> 0 | K2: =SUM(L2:U2) -> 0 | L2: 0 | M2: 0 | N2: 0 | O2: 0 | P2: 0 | Q2: 0 | R2: 0 | S2: 0 | T2: 0 | U2: 0 | V2: 0 | W2: 0 | X2: 0 | Y2: 0 | Z2: 0 | AA2: 0 | AB2: 0 | AC2: 0 | AD2: 0 | AE2: 0 | AF2: 0 | AG2: 0 | AH2: 0 | AI2: 1 | AJ2: 0 | AK2: 0 | AL2: 0 | AM2: 0 | AN2: 0 | AO2: 0 | AP2: 0 | AQ2: 0 | AR2: 0 | AS2: 0 | AT2: 0 | AU2: 0 | AV2: 0 | AW2: 0 | AX2: 0
B3: 46168 | C3: Weisshorn | D3: 15BW49B001 | E3: L3 | F3: 3 | G3: =F3*21 -> 63 | H3: =1-I3/G3 -> 0.98412698 | I3: =SUM(L3:AX3) -> 1 | J3: =K3/G3 -> 0.015873016 | K3: =SUM(L3:U3) -> 1 | L3: 0 | M3: 0 | N3: 0 | O3: 0 | P3: 0 | Q3: 1 | R3: 0 | S3: 0 | T3: 0 | U3: 0 | V3: 0 | W3: 0 | X3: 0 | Y3: 0 | Z3: 0 | AA3: 0 | AB3: 0 | AC3: 0 | AD3: 0 | AE3: 0 | AF3: 0 | AG3: 0 | AH3: 0 | AI3: 0 | AJ3: 0 | AK3: 0 | AL3: 0 | AM3: 0 | AN3: 0 | AO3: 0 | AP3: 0 | AQ3: 0 | AR3: 0 | AS3: 0 | AT3: 0 | AU3: 0 | AV3: 0 | AW3: 0 | AX3: 0
B4: 46168 | C4: Weisshorn | D4: 16BW65 | E4: L3 | F4: 3 | G4: =F4*21 -> 63 | H4: =1-I4/G4 -> 1 | I4: =SUM(L4:AX4) -> 0 | J4: =K4/G4 -> 0 | K4: =SUM(L4:U4) -> 0 | L4: 0 | M4: 0 | N4: 0 | O4: 0 | P4: 0 | Q4: 0 | R4: 0 | S4: 0 | T4: 0 | U4: 0 | V4: 0 | W4: 0 | X4: 0 | Y4: 0 | Z4: 0 | AA4: 0 | AB4: 0 | AC4: 0 | AD4: 0 | AE4: 0 | AF4: 0 | AG4: 0 | AH4: 0 | AI4: 0 | AJ4: 0 | AK4: 0 | AL4: 0 | AM4: 0 | AN4: 0 | AO4: 0 | AP4: 0 | AQ4: 0 | AR4: 0 | AS4: 0 | AT4: 0 | AU4: 0 | AV4: 0 | AW4: 0 | AX4: 0 | AY4: 6688 扣過量 #11 (0,2)
B5: 46168 | C5: Weisshorn | D5: 04BW1NB002 | E5: L2 | F5: 2 | G5: =F5*21 -> 42 | H5: =1-I5/G5 -> 0.97619048 | I5: =SUM(L5:AX5) -> 1 | J5: =K5/G5 -> 0.023809524 | K5: =SUM(L5:U5) -> 1 | L5: 0 | M5: 0 | N5: 1 | O5: 0 | P5: 0 | Q5: 0 | R5: 0 | S5: 0 | T5: 0 | U5: 0 | V5: 0 | W5: 0 | X5: 0 | Y5: 0 | Z5: 0 | AA5: 0 | AB5: 0 | AC5: 0 | AD5: 0 | AE5: 0 | AF5: 0 | AG5: 0 | AH5: 0 | AI5: 0 | AJ5: 0 | AK5: 0 | AL5: 0 | AM5: 0 | AN5: 0 | AO5: 0 | AP5: 0 | AQ5: 0 | AR5: 0 | AS5: 0 | AT5: 0 | AU5: 0 | AV5: 0 | AW5: 0 | AX5: 0
B6: 46168 | C6: Weisshorn | D6: 17BW28B001 | E6: L1 | F6: 1 | G6: =F6*21 -> 21 | H6: =1-I6/G6 -> 1 | I6: =SUM(L6:AX6) -> 0 | J6: =K6/G6 -> 0 | K6: =SUM(L6:U6) -> 0 | L6: 0 | M6: 0 | N6: 0 | O6: 0 | P6: 0 | Q6: 0 | R6: 0 | S6: 0 | T6: 0 | U6: 0 | V6: 0 | W6: 0 | X6: 0 | Y6: 0 | Z6: 0 | AA6: 0 | AB6: 0 | AC6: 0 | AD6: 0 | AE6: 0 | AF6: 0 | AG6: 0 | AH6: 0 | AI6: 0 | AJ6: 0 | AK6: 0 | AL6: 0 | AM6: 0 | AN6: 0 | AO6: 0 | AP6: 0 | AQ6: 0 | AR6: 0 | AS6: 0 | AT6: 0 | AU6: 0 | AV6: 0 | AW6: 0 | AX6: 0
B7: 46168 | C7: Weisshorn | D7: 17BW28 | E7: L1 | F7: 3 | G7: =F7*21 -> 63 | H7: =1-I7/G7 -> 1 | I7: =SUM(L7:AX7) -> 0 | J7: =K7/G7 -> 0 | K7: =SUM(L7:U7) -> 0 | L7: 0 | M7: 0 | N7: 0 | O7: 0 | P7: 0 | Q7: 0 | R7: 0 | S7: 0 | T7: 0 | U7: 0 | V7: 0 | W7: 0 | X7: 0 | Y7: 0 | Z7: 0 | AA7: 0 | AB7: 0 | AC7: 0 | AD7: 0 | AE7: 0 | AF7: 0 | AG7: 0 | AH7: 0 | AI7: 0 | AJ7: 0 | AK7: 0 | AL7: 0 | AM7: 0 | AN7: 0 | AO7: 0 | AP7: 0 | AQ7: 0 | AR7: 0 | AS7: 0 | AT7: 0 | AU7: 0 | AV7: 0 | AW7: 0 | AX7: 0
A8: W23 | B8: 46169 | C8: Weisshorn | D8: 15BW53B002 | E8: L3 | F8: 1 | G8: =F8*21 -> 21 | H8: =1-I8/G8 -> 0.9047619 | I8: =SUM(L8:AX8) -> 2 | J8: =K8/G8 -> 0 | K8: =SUM(L8:U8) -> 0 | L8: 0 | M8: 0 | N8: 0 | O8: 0 | P8: 0 | Q8: 0 | R8: 0 | S8: 0 | T8: 0 | U8: 0 | V8: 0 | W8: 0 | X8: 2 | Y8: 0 | Z8: 0 | AA8: 0 | AB8: 0 | AC8: 0 | AD8: 0 | AE8: 0 | AF8: 0 | AG8: 0 | AH8: 0 | AI8: 0 | AJ8: 0 | AK8: 0 | AL8: 0 | AM8: 0 | AN8: 0 | AO8: 0 | AP8: 0 | AQ8: 0 | AR8: 0 | AS8: 0 | AT8: 0 | AU8: 0 | AV8: 0 | AW8: 0 | AX8: 0
B9: 46169 | C9: Weisshorn | D9: 16BW75B001 | E9: L3 | F9: 1 | G9: =F9*21 -> 21 | H9: =1-I9/G9 -> 0.95238095 | I9: =SUM(L9:AX9) -> 1 | J9: =K9/G9 -> 0 | K9: =SUM(L9:U9) -> 0 | L9: 0 | M9: 0 | N9: 0 | O9: 0 | P9: 0 | Q9: 0 | R9: 0 | S9: 0 | T9: 0 | U9: 0 | V9: 0 | W9: 0 | X9: 1 | Y9: 0 | Z9: 0 | AA9: 0 | AB9: 0 | AC9: 0 | AD9: 0 | AE9: 0 | AF9: 0 | AG9: 0 | AH9: 0 | AI9: 0 | AJ9: 0 | AK9: 0 | AL9: 0 | AM9: 0 | AN9: 0 | AO9: 0 | AP9: 0 | AQ9: 0 | AR9: 0 | AS9: 0 | AT9: 0 | AU9: 0 | AV9: 0 | AW9: 0 | AX9: 0
B10: 46169 | C10: Weisshorn | D10: 16BW73B001 | E10: L2 | F10: 1 | G10: =F10*21 -> 21 | H10: =1-I10/G10 -> 0.9047619 | I10: =SUM(L10:AX10) -> 2 | J10: =K10/G10 -> 0.095238095 | K10: =SUM(L10:U10) -> 2 | L10: 0 | M10: 0 | N10: 0 | O10: 0 | P10: 2 | Q10: 0 | R10: 0 | S10: 0 | T10: 0 | U10: 0 | V10: 0 | W10: 0 | X10: 0 | Y10: 0 | Z10: 0 | AA10: 0 | AB10: 0 | AC10: 0 | AD10: 0 | AE10: 0 | AF10: 0 | AG10: 0 | AH10: 0 | AI10: 0 | AJ10: 0 | AK10: 0 | AL10: 0 | AM10: 0 | AN10: 0 | AO10: 0 | AP10: 0 | AQ10: 0 | AR10: 0 | AS10: 0 | AT10: 0 | AU10: 0 | AV10: 0 | AW10: 0 | AX10: 0
B11: 46169 | C11: Weisshorn | D11: 15BW52 | E11: L3 | F11: 1 | G11: =F11*21 -> 21 | H11: =1-I11/G11 -> 1 | I11: =SUM(L11:AX11) -> 0 | J11: =K11/G11 -> 0 | K11: =SUM(L11:U11) -> 0 | L11: 0 | M11: 0 | N11: 0 | O11: 0 | P11: 0 | Q11: 0 | R11: 0 | S11: 0 | T11: 0 | U11: 0 | V11: 0 | W11: 0 | X11: 0 | Y11: 0 | Z11: 0 | AA11: 0 | AB11: 0 | AC11: 0 | AD11: 0 | AE11: 0 | AF11: 0 | AG11: 0 | AH11: 0 | AI11: 0 | AJ11: 0 | AK11: 0 | AL11: 0 | AM11: 0 | AN11: 0 | AO11: 0 | AP11: 0 | AQ11: 0 | AR11: 0 | AS11: 0 | AT11: 0 | AU11: 0 | AV11: 0 | AW11: 0 | AX11: 0
B12: 46169 | C12: Weisshorn | D12: 16BW64 | E12: L3 | F12: 1 | G12: =F12*21 -> 21 | H12: =1-I12/G12 -> 1 | I12: =SUM(L12:AX12) -> 0 | J12: =K12/G12 -> 0 | K12: =SUM(L12:U12) -> 0 | L12: 0 | M12: 0 | N12: 0 | O12: 0 | P12: 0 | Q12: 0 | R12: 0 | S12: 0 | T12: 0 | U12: 0 | V12: 0 | W12: 0 | X12: 0 | Y12: 0 | Z12: 0 | AA12: 0 | AB12: 0 | AC12: 0 | AD12: 0 | AE12: 0 | AF12: 0 | AG12: 0 | AH12: 0 | AI12: 0 | AJ12: 0 | AK12: 0 | AL12: 0 | AM12: 0 | AN12: 0 | AO12: 0 | AP12: 0 | AQ12: 0 | AR12: 0 | AS12: 0 | AT12: 0 | AU12: 0 | AV12: 0 | AW12: 0 | AX12: 0
B13: 46169 | C13: Weisshorn | D13: 16BW72 | E13: L3 | F13: 1 | G13: =F13*21 -> 21 | H13: =1-I13/G13 -> 1 | I13: =SUM(L13:AX13) -> 0 | J13: =K13/G13 -> 0 | K13: =SUM(L13:U13) -> 0 | L13: 0 | M13: 0 | N13: 0 | O13: 0 | P13: 0 | Q13: 0 | R13: 0 | S13: 0 | T13: 0 | U13: 0 | V13: 0 | W13: 0 | X13: 0 | Y13: 0 | Z13: 0 | AA13: 0 | AB13: 0 | AC13: 0 | AD13: 0 | AE13: 0 | AF13: 0 | AG13: 0 | AH13: 0 | AI13: 0 | AJ13: 0 | AK13: 0 | AL13: 0 | AM13: 0 | AN13: 0 | AO13: 0 | AP13: 0 | AQ13: 0 | AR13: 0 | AS13: 0 | AT13: 0 | AU13: 0 | AV13: 0 | AW13: 0 | AX13: 0
B14: 46169 | C14: Weisshorn | D14: 15BW52B001 | E14: L3 | F14: 1 | G14: =F14*21 -> 21 | H14: =1-I14/G14 -> 1 | I14: =SUM(L14:AX14) -> 0 | J14: =K14/G14 -> 0 | K14: =SUM(L14:U14) -> 0 | L14: 0 | M14: 0 | N14: 0 | O14: 0 | P14: 0 | Q14: 0 | R14: 0 | S14: 0 | T14: 0 | U14: 0 | V14: 0 | W14: 0 | X14: 0 | Y14: 0 | Z14: 0 | AA14: 0 | AB14: 0 | AC14: 0 | AD14: 0 | AE14: 0 | AF14: 0 | AG14: 0 | AH14: 0 | AI14: 0 | AJ14: 0 | AK14: 0 | AL14: 0 | AM14: 0 | AN14: 0 | AO14: 0 | AP14: 0 | AQ14: 0 | AR14: 0 | AS14: 0 | AT14: 0 | AU14: 0 | AV14: 0 | AW14: 0 | AX14: 0
B15: 46170 | C15: Weisshorn | D15: 15BW46B002 | E15: L3 | F15: 2 | G15: =F15*21 -> 42 | H15: =1-I15/G15 -> 0.97619048 | I15: =SUM(L15:AX15) -> 1 | J15: =K15/G15 -> 0 | K15: =SUM(L15:U15) -> 0 | L15: 0 | M15: 0 | N15: 0 | O15: 0 | P15: 0 | Q15: 0 | R15: 0 | S15: 0 | T15: 0 | U15: 0 | V15: 0 | W15: 0 | X15: 0 | Y15: 0 | Z15: 0 | AA15: 1 | AB15: 0 | AC15: 0 | AD15: 0 | AE15: 0 | AF15: 0 | AG15: 0 | AH15: 0 | AI15: 0 | AJ15: 0 | AK15: 0 | AL15: 0 | AM15: 0 | AN15: 0 | AO15: 0 | AP15: 0 | AQ15: 0 | AR15: 0 | AS15: 0 | AT15: 0 | AU15: 0 | AV15: 0 | AW15: 0 | AX15: 0
B16: 46170 | C16: Weisshorn | D16: 15BW46B003 | E16: L3 | F16: 5 | G16: =F16*21 -> 105 | H16: =1-I16/G16 -> 0.95238095 | I16: =SUM(L16:AX16) -> 5 | J16: =K16/G16 -> 0.047619048 | K16: =SUM(L16:U16) -> 5 | L16: 0 | M16: 5 | N16: 0 | O16: 0 | P16: 0 | Q16: 0 | R16: 0 | S16: 0 | T16: 0 | U16: 0 | V16: 0 | W16: 0 | X16: 0 | Y16: 0 | Z16: 0 | AA16: 0 | AB16: 0 | AC16: 0 | AD16: 0 | AE16: 0 | AF16: 0 | AG16: 0 | AH16: 0 | AI16: 0 | AJ16: 0 | AK16: 0 | AL16: 0 | AM16: 0 | AN16: 0 | AO16: 0 | AP16: 0 | AQ16: 0 | AR16: 0 | AS16: 0 | AT16: 0 | AU16: 0 | AV16: 0 | AW16: 0 | AX16: 0
B17: 46170 | C17: Weisshorn | D17: 15BW50B001 | E17: L3 | F17: 1 | G17: =F17*21 -> 21 | H17: =1-I17/G17 -> 0.95238095 | I17: =SUM(L17:AX17) -> 1 | J17: =K17/G17 -> 0.047619048 | K17: =SUM(L17:U17) -> 1 | L17: 0 | M17: 1 | N17: 0 | O17: 0 | P17: 0 | Q17: 0 | R17: 0 | S17: 0 | T17: 0 | U17: 0 | V17: 0 | W17: 0 | X17: 0 | Y17: 0 | Z17: 0 | AA17: 0 | AB17: 0 | AC17: 0 | AD17: 0 | AE17: 0 | AF17: 0 | AG17: 0 | AH17: 0 | AI17: 0 | AJ17: 0 | AK17: 0 | AL17: 0 | AM17: 0 | AN17: 0 | AO17: 0 | AP17: 0 | AQ17: 0 | AR17: 0 | AS17: 0 | AT17: 0 | AU17: 0 | AV17: 0 | AW17: 0 | AX17: 0
B18: 46170 | C18: Weisshorn | D18: 16BW73B001 | E18: L3 | F18: 1 | G18: =F18*21 -> 21 | H18: =1-I18/G18 -> 1 | I18: =SUM(L18:AX18) -> 0 | J18: =K18/G18 -> 0 | K18: =SUM(L18:U18) -> 0 | L18: 0 | M18: 0 | N18: 0 | O18: 0 | P18: 0 | Q18: 0 | R18: 0 | S18: 0 | T18: 0 | U18: 0 | V18: 0 | W18: 0 | X18: 0 | Y18: 0 | Z18: 0 | AA18: 0 | AB18: 0 | AC18: 0 | AD18: 0 | AE18: 0 | AF18: 0 | AG18: 0 | AH18: 0 | AI18: 0 | AJ18: 0 | AK18: 0 | AL18: 0 | AM18: 0 | AN18: 0 | AO18: 0 | AP18: 0 | AQ18: 0 | AR18: 0 | AS18: 0 | AT18: 0 | AU18: 0 | AV18: 0 | AW18: 0 | AX18: 0
B19: 46170 | C19: Weisshorn | D19: 17BW31B001 | E19: L3 | F19: 1 | G19: =F19*21 -> 21 | H19: =1-I19/G19 -> 0.95238095 | I19: =SUM(L19:AX19) -> 1 | J19: =K19/G19 -> 0 | K19: =SUM(L19:U19) -> 0 | L19: 0 | M19: 0 | N19: 0 | O19: 0 | P19: 0 | Q19: 0 | R19: 0 | S19: 0 | T19: 0 | U19: 0 | V19: 0 | W19: 0 | X19: 0 | Y19: 0 | Z19: 0 | AA19: 1 | AB19: 0 | AC19: 0 | AD19: 0 | AE19: 0 | AF19: 0 | AG19: 0 | AH19: 0 | AI19: 0 | AJ19: 0 | AK19: 0 | AL19: 0 | AM19: 0 | AN19: 0 | AO19: 0 | AP19: 0 | AQ19: 0 | AR19: 0 | AS19: 0 | AT19: 0 | AU19: 0 | AV19: 0 | AW19: 0 | AX19: 0
B20: 46170 | C20: Weisshorn | D20: 17BW88 | E20: L3 | F20: 1 | G20: =F20*21 -> 21 | H20: =1-I20/G20 -> 1 | I20: =SUM(L20:AX20) -> 0 | J20: =K20/G20 -> 0 | K20: =SUM(L20:U20) -> 0 | L20: 0 | M20: 0 | N20: 0 | O20: 0 | P20: 0 | Q20: 0 | R20: 0 | S20: 0 | T20: 0 | U20: 0 | V20: 0 | W20: 0 | X20: 0 | Y20: 0 | Z20: 0 | AA20: 0 | AB20: 0 | AC20: 0 | AD20: 0 | AE20: 0 | AF20: 0 | AG20: 0 | AH20: 0 | AI20: 0 | AJ20: 0 | AK20: 0 | AL20: 0 | AM20: 0 | AN20: 0 | AO20: 0 | AP20: 0 | AQ20: 0 | AR20: 0 | AS20: 0 | AT20: 0 | AU20: 0 | AV20: 0 | AW20: 0 | AX20: 0
... B23: 46174 | C23: Weisshorn | D23: 17BW30 | E23: L3 | F23: 1 | G23: =F23*21 -> 21 | H23: =1-I23/G23 -> 1 | I23: =SUM(L23:AX23) -> 0 | J23: =K23/G23 -> 0 | K23: =SUM(L23:U23) -> 0 | L23: 0 | M23: 0 | N23: 0 | O23: 0 | P23: 0 | Q23: 0 | R23: 0 | S23: 0 | T23: 0 | U23: 0 | V23: 0 | W23: 0 | X23: 0 | Y23: 0 | Z23: 0 | AA23: 0 | AB23: 0 | AC23: 0 | AD23: 0 | AE23: 0 | AF23: 0 | AG23: 0 | AH23: 0 | AI23: 0 | AJ23: 0 | AK23: 0 | AL23: 0 | AM23: 0 | AN23: 0 | AO23: 0 | AP23: 0 | AQ23: 0 | AR23: 0 | AS23: 0 | AT23: 0 | AU23: 0 | AV23: 0 | AW23: 0 | AX23: 0
B24: 46174 | C24: Weisshorn | D24: 15BW46B004 | E24: L2 | F24: 1 | G24: =F24*21 -> 21 | H24: =1-I24/G24 -> 1 | I24: =SUM(L24:AX24) -> 0 | J24: =K24/G24 -> 0 | K24: =SUM(L24:U24) -> 0 | L24: 0 | M24: 0 | N24: 0 | O24: 0 | P24: 0 | Q24: 0 | R24: 0 | S24: 0 | T24: 0 | U24: 0 | V24: 0 | W24: 0 | X24: 0 | Y24: 0 | Z24: 0 | AA24: 0 | AB24: 0 | AC24: 0 | AD24: 0 | AE24: 0 | AF24: 0 | AG24: 0 | AH24: 0 | AI24: 0 | AJ24: 0 | AK24: 0 | AL24: 0 | AM24: 0 | AN24: 0 | AO24: 0 | AP24: 0 | AQ24: 0 | AR24: 0 | AS24: 0 | AT24: 0 | AU24: 0 | AV24: 0 | AW24: 0 | AX24: 0 | AY24: 5/13 API2 PI Cure*2 Final*2
B25: 46174 | C25: Weisshorn | D25: 15BW50B002 | E25: L2 | F25: 1 | G25: =F25*21 -> 21 | H25: =1-I25/G25 -> 1 | I25: =SUM(L25:AX25) -> 0 | J25: =K25/G25 -> 0 | K25: =SUM(L25:U25) -> 0 | L25: 0 | M25: 0 | N25: 0 | O25: 0 | P25: 0 | Q25: 0 | R25: 0 | S25: 0 | T25: 0 | U25: 0 | V25: 0 | W25: 0 | X25: 0 | Y25: 0 | Z25: 0 | AA25: 0 | AB25: 0 | AC25: 0 | AD25: 0 | AE25: 0 | AF25: 0 | AG25: 0 | AH25: 0 | AI25: 0 | AJ25: 0 | AK25: 0 | AL25: 0 | AM25: 0 | AN25: 0 | AO25: 0 | AP25: 0 | AQ25: 0 | AR25: 0 | AS25: 0 | AT25: 0 | AU25: 0 | AV25: 0 | AW25: 0 | AX25: 0
B26: 46174 | C26: Weisshorn | D26: 16BW93B002 | E26: L2 | F26: 1 | G26: =F26*21 -> 21 | H26: =1-I26/G26 -> 0.95238095 | I26: =SUM(L26:AX26) -> 1 | J26: =K26/G26 -> 0.047619048 | K26: =SUM(L26:U26) -> 1 | L26: 0 | M26: 0 | N26: 0 | O26: 1 | P26: 0 | Q26: 0 | R26: 0 | S26: 0 | T26: 0 | U26: 0 | V26: 0 | W26: 0 | X26: 0 | Y26: 0 | Z26: 0 | AA26: 0 | AB26: 0 | AC26: 0 | AD26: 0 | AE26: 0 | AF26: 0 | AG26: 0 | AH26: 0 | AI26: 0 | AJ26: 0 | AK26: 0 | AL26: 0 | AM26: 0 | AN26: 0 | AO26: 0 | AP26: 0 | AQ26: 0 | AR26: 0 | AS26: 0 | AT26: 0 | AU26: 0 | AV26: 0 | AW26: 0 | AX26: 0
B27: 46174 | C27: Weisshorn | D27: 17BW28 | E27: L2 | F27: 3 | G27: =F27*21 -> 63 | H27: =1-I27/G27 -> 1 | I27: =SUM(L27:AX27) -> 0 | J27: =K27/G27 -> 0 | K27: =SUM(L27:U27) -> 0 | L27: 0 | M27: 0 | N27: 0 | O27: 0 | P27: 0 | Q27: 0 | R27: 0 | S27: 0 | T27: 0 | U27: 0 | V27: 0 | W27: 0 | X27: 0 | Y27: 0 | Z27: 0 | AA27: 0 | AB27: 0 | AC27: 0 | AD27: 0 | AE27: 0 | AF27: 0 | AG27: 0 | AH27: 0 | AI27: 0 | AJ27: 0 | AK27: 0 | AL27: 0 | AM27: 0 | AN27: 0 | AO27: 0 | AP27: 0 | AQ27: 0 | AR27: 0 | AS27: 0 | AT27: 0 | AU27: 0 | AV27: 0 | AW27: 0 | AX27: 0
B28: 46176 | C28: Weisshorn | D28: 15BW43B003 | E28: L3 | F28: 1 | G28: =F28*21 -> 21 | H28: =1-I28/G28 -> 0.95238095 | I28: =SUM(L28:AX28) -> 1 | J28: =K28/G28 -> 0 | K28: =SUM(L28:U28) -> 0 | L28: 0 | M28: 0 | N28: 0 | O28: 0 | P28: 0 | Q28: 0 | R28: 0 | S28: 0 | T28: 0 | U28: 0 | V28: 0 | W28: 0 | X28: 0 | Y28: 0 | Z28: 0 | AA28: 1 | AB28: 0 | AC28: 0 | AD28: 0 | AE28: 0 | AF28: 0 | AG28: 0 | AH28: 0 | AI28: 0 | AJ28: 0 | AK28: 0 | AL28: 0 | AM28: 0 | AN28: 0 | AO28: 0 | AP28: 0 | AQ28: 0 | AR28: 0 | AS28: 0 | AT28: 0 | AU28: 0 | AV28: 0 | AW28: 0 | AX28: 0
B29: 46176 | C29: Weisshorn | D29: 17BW30B001 | E29: L1 | F29: 2 | G29: =F29*21 -> 42 | H29: =1-I29/G29 -> 1 | I29: =SUM(L29:AX29) -> 0 | J29: =K29/G29 -> 0 | K29: =SUM(L29:U29) -> 0 | L29: 0 | M29: 0 | N29: 0 | O29: 0 | P29: 0 | Q29: 0 | R29: 0 | S29: 0 | T29: 0 | U29: 0 | V29: 0 | W29: 0 | X29: 0 | Y29: 0 | Z29: 0 | AA29: 0 | AB29: 0 | AC29: 0 | AD29: 0 | AE29: 0 | AF29: 0 | AG29: 0 | AH29: 0 | AI29: 0 | AJ29: 0 | AK29: 0 | AL29: 0 | AM29: 0 | AN29: 0 | AO29: 0 | AP29: 0 | AQ29: 0 | AR29: 0 | AS29: 0 | AT29: 0 | AU29: 0 | AV29: 0 | AW29: 0 | AX29: 0
A30: W24 | B30: 46177 | C30: Weisshorn | D30: 16BW74B001 | E30: L3 | F30: 2 | G30: =F30*21 -> 42 | H30: =1-I30/G30 -> 1 | I30: =SUM(L30:AX30) -> 0 | J30: =K30/G30 -> 0 | K30: =SUM(L30:U30) -> 0 | L30: 0 | M30: 0 | N30: 0 | O30: 0 | P30: 0 | Q30: 0 | R30: 0 | S30: 0 | T30: 0 | U30: 0 | V30: 0 | W30: 0 | X30: 0 | Y30: 0 | Z30: 0 | AA30: 0 | AB30: 0 | AC30: 0 | AD30: 0 | AE30: 0 | AF30: 0 | AG30: 0 | AH30: 0 | AI30: 0 | AJ30: 0 | AK30: 0 | AL30: 0 | AM30: 0 | AN30: 0 | AO30: 0 | AP30: 0 | AQ30: 0 | AR30: 0 | AS30: 0 | AT30: 0 | AU30: 0 | AV30: 0 | AW30: 0 | AX30: 0
B31: 46177 | C31: Weisshorn | D31: 16BW64B001 | E31: L2 | F31: 1 | G31: =F31*21 -> 21 | H31: =1-I31/G31 -> 1 | I31: =SUM(L31:AX31) -> 0 | J31: =K31/G31 -> 0 | K31: =SUM(L31:U31) -> 0 | L31: 0 | M31: 0 | N31: 0 | O31: 0 | P31: 0 | Q31: 0 | R31: 0 | S31: 0 | T31: 0 | U31: 0 | V31: 0 | W31: 0 | X31: 0 | Y31: 0 | Z31: 0 | AA31: 0 | AB31: 0 | AC31: 0 | AD31: 0 | AE31: 0 | AF31: 0 | AG31: 0 | AH31: 0 | AI31: 0 | AJ31: 0 | AK31: 0 | AL31: 0 | AM31: 0 | AN31: 0 | AO31: 0 | AP31: 0 | AQ31: 0 | AR31: 0 | AS31: 0 | AT31: 0 | AU31: 0 | AV31: 0 | AW31: 0 | AX31: 0
B32: 46178 | C32: Weisshorn | D32: 15BW45 | E32: L3 | F32: 6 | G32: =F32*21 -> 126 | H32: =1-I32/G32 -> 0.98412698 | I32: =SUM(L32:AX32) -> 2 | J32: =K32/G32 -> 0.0079365079 | K32: =SUM(L32:U32) -> 1 | L32: 0 | M32: 0 | N32: 1 | O32: 0 | P32: 0 | Q32: 0 | R32: 0 | S32: 0 | T32: 0 | U32: 0 | V32: 1 | W32: 0 | X32: 0 | Y32: 0 | Z32: 0 | AA32: 0 | AB32: 0 | AC32: 0 | AD32: 0 | AE32: 0 | AF32: 0 | AG32: 0 | AH32: 0 | AI32: 0 | AJ32: 0 | AK32: 0 | AL32: 0 | AM32: 0 | AN32: 0 | AO32: 0 | AP32: 0 | AQ32: 0 | AR32: 0 | AS32: 0 | AT32: 0 | AU32: 0 | AV32: 0 | AW32: 0 | AX32: 0
B33: 46178 | C33: Weisshorn | D33: 15BW50B002 | E33: L3 | F33: 1 | G33: =F33*21 -> 21 | H33: =1-I33/G33 -> 1 | I33: =SUM(L33:AX33) -> 0 | J33: =K33/G33 -> 0 | K33: =SUM(L33:U33) -> 0 | L33: 0 | M33: 0 | N33: 0 | O33: 0 | P33: 0 | Q33: 0 | R33: 0 | S33: 0 | T33: 0 | U33: 0 | V33: 0 | W33: 0 | X33: 0 | Y33: 0 | Z33: 0 | AA33: 0 | AB33: 0 | AC33: 0 | AD33: 0 | AE33: 0 | AF33: 0 | AG33: 0 | AH33: 0 | AI33: 0 | AJ33: 0 | AK33: 0 | AL33: 0 | AM33: 0 | AN33: 0 | AO33: 0 | AP33: 0 | AQ33: 0 | AR33: 0 | AS33: 0 | AT33: 0 | AU33: 0 | AV33: 0 | AW33: 0 | AX33: 0
B34: 46181 | C34: Weisshorn | D34: 04BW1N | E34: L1 | F34: 4 | G34: =F34*21 -> 84 | H34: =1-I34/G34 -> 1 | I34: =SUM(L34:AX34) -> 0 | J34: =K34/G34 -> 0 | K34: =SUM(L34:U34) -> 0 | L34: 0 | M34: 0 | N34: 0 | O34: 0 | P34: 0 | Q34: 0 | R34: 0 | S34: 0 | T34: 0 | U34: 0 | V34: 0 | W34: 0 | X34: 0 | Y34: 0 | Z34: 0 | AA34: 0 | AB34: 0 | AC34: 0 | AD34: 0 | AE34: 0 | AF34: 0 | AG34: 0 | AH34: 0 | AI34: 0 | AJ34: 0 | AK34: 0 | AL34: 0 | AM34: 0 | AN34: 0 | AO34: 0 | AP34: 0 | AQ34: 0 | AR34: 0 | AS34: 0 | AT34: 0 | AU34: 0 | AV34: 0 | AW34: 0 | AX34: 0
B35: 46181 | C35: Weisshorn | D35: 15BW45B001 | E35: L2 | F35: 6 | G35: =F35*21 -> 126 | H35: =1-I35/G35 -> 0.97619048 | I35: =SUM(L35:AX35) -> 3 | J35: =K35/G35 -> 0.023809524 | K35: =SUM(L35:U35) -> 3 | L35: 0 | M35: 0 | N35: 1 | O35: 0 | P35: 0 | Q35: 1 | R35: 0 | S35: 1 | T35: 0 | U35: 0 | V35: 0 | W35: 0 | X35: 0 | Y35: 0 | Z35: 0 | AA35: 0 | AB35: 0 | AC35: 0 | AD35: 0 | AE35: 0 | AF35: 0 | AG35: 0 | AH35: 0 | AI35: 0 | AJ35: 0 | AK35: 0 | AL35: 0 | AM35: 0 | AN35: 0 | AO35: 0 | AP35: 0 | AQ35: 0 | AR35: 0 | AS35: 0 | AT35: 0 | AU35: 0 | AV35: 0 | AW35: 0 | AX35: 0 | AY35: 6/4 API2 Sput*1
B36: 46181 | C36: Weisshorn | D36: 17BW28B002 | E36: L1 | F36: 1 | G36: =F36*21 -> 21 | H36: =1-I36/G36 -> 1 | I36: =SUM(L36:AX36) -> 0 | J36: =K36/G36 -> 0 | K36: =SUM(L36:U36) -> 0 | L36: 0 | M36: 0 | N36: 0 | O36: 0 | P36: 0 | Q36: 0 | R36: 0 | S36: 0 | T36: 0 | U36: 0 | V36: 0 | W36: 0 | X36: 0 | Y36: 0 | Z36: 0 | AA36: 0 | AB36: 0 | AC36: 0 | AD36: 0 | AE36: 0 | AF36: 0 | AG36: 0 | AH36: 0 | AI36: 0 | AJ36: 0 | AK36: 0 | AL36: 0 | AM36: 0 | AN36: 0 | AO36: 0 | AP36: 0 | AQ36: 0 | AR36: 0 | AS36: 0 | AT36: 0 | AU36: 0 | AV36: 0 | AW36: 0 | AX36: 0
B37: 46181 | C37: Weisshorn | D37: 17BW30B001 | E37: L2 | F37: 2 | G37: =F37*21 -> 42 | H37: =1-I37/G37 -> 1 | I37: =SUM(L37:AX37) -> 0 | J37: =K37/G37 -> 0 | K37: =SUM(L37:U37) -> 0 | L37: 0 | M37: 0 | N37: 0 | O37: 0 | P37: 0 | Q37: 0 | R37: 0 | S37: 0 | T37: 0 | U37: 0 | V37: 0 | W37: 0 | X37: 0 | Y37: 0 | Z37: 0 | AA37: 0 | AB37: 0 | AC37: 0 | AD37: 0 | AE37: 0 | AF37: 0 | AG37: 0 | AH37: 0 | AI37: 0 | AJ37: 0 | AK37: 0 | AL37: 0 | AM37: 0 | AN37: 0 | AO37: 0 | AP37: 0 | AQ37: 0 | AR37: 0 | AS37: 0 | AT37: 0 | AU37: 0 | AV37: 0 | AW37: 0 | AX37: 0
B38: 46182 | C38: Weisshorn | D38: 15BW45B002 | E38: L2 | F38: 1 | G38: =F38*21 -> 21 | H38: =1-I38/G38 -> 1 | I38: =SUM(L38:AX38) -> 0 | J38: =K38/G38 -> 0 | K38: =SUM(L38:U38) -> 0 | L38: 0 | M38: 0 | N38: 0 | O38: 0 | P38: 0 | Q38: 0 | R38: 0 | S38: 0 | T38: 0 | U38: 0 | V38: 0 | W38: 0 | X38: 0 | Y38: 0 | Z38: 0 | AA38: 0 | AB38: 0 | AC38: 0 | AD38: 0 | AE38: 0 | AF38: 0 | AG38: 0 | AH38: 0 | AI38: 0 | AJ38: 0 | AK38: 0 | AL38: 0 | AM38: 0 | AN38: 0 | AO38: 0 | AP38: 0 | AQ38: 0 | AR38: 0 | AS38: 0 | AT38: 0 | AU38: 0 | AV38: 0 | AW38: 0 | AX38: 0 | AY38: 6581 扣過量 #7 (3,0)
B39: 46182 | C39: Weisshorn | D39: 16BW74 | E39: L3 | F39: 4 | G39: =F39*21 -> 84 | H39: =1-I39/G39 -> 1 | I39: =SUM(L39:AX39) -> 0 | J39: =K39/G39 -> 0 | K39: =SUM(L39:U39) -> 0 | L39: 0 | M39: 0 | N39: 0 | O39: 0 | P39: 0 | Q39: 0 | R39: 0 | S39: 0 | T39: 0 | U39: 0 | V39: 0 | W39: 0 | X39: 0 | Y39: 0 | Z39: 0 | AA39: 0 | AB39: 0 | AC39: 0 | AD39: 0 | AE39: 0 | AF39: 0 | AG39: 0 | AH39: 0 | AI39: 0 | AJ39: 0 | AK39: 0 | AL39: 0 | AM39: 0 | AN39: 0 | AO39: 0 | AP39: 0 | AQ39: 0 | AR39: 0 | AS39: 0 | AT39: 0 | AU39: 0 | AV39: 0 | AW39: 0 | AX39: 0
B40: 46183 | C40: Weisshorn | D40: 16BW64B001 | E40: L3 | F40: 1 | G40: =F40*21 -> 21 | H40: =1-I40/G40 -> 1 | I40: =SUM(L40:AX40) -> 0 | J40: =K40/G40 -> 0 | K40: =SUM(L40:U40) -> 0 | L40: 0 | M40: 0 | N40: 0 | O40: 0 | P40: 0 | Q40: 0 | R40: 0 | S40: 0 | T40: 0 | U40: 0 | V40: 0 | W40: 0 | X40: 0 | Y40: 0 | Z40: 0 | AA40: 0 | AB40: 0 | AC40: 0 | AD40: 0 | AE40: 0 | AF40: 0 | AG40: 0 | AH40: 0 | AI40: 0 | AJ40: 0 | AK40: 0 | AL40: 0 | AM40: 0 | AN40: 0 | AO40: 0 | AP40: 0 | AQ40: 0 | AR40: 0 | AS40: 0 | AT40: 0 | AU40: 0 | AV40: 0 | AW40: 0 | AX40: 0
